INFO:httpx:HTTP Request: POST https://api.telegram.org/bot7779786808:AAHul6zZde15UvoPbGb5aMm-KvtvROpqfB8/getMe "HTTP/1.1 200 OK"
INFO:httpx:HTTP Request: POST https://api.telegram.org/bot7779786808:AAHul6zZde15UvoPbGb5aMm-KvtvROpqfB8/deleteWebhook "HTTP/1.1 200 OK"
INFO:telegram.ext.Application:Application started
INFO:httpx:HTTP Request: POST https://api.telegram.org/bot7779786808:AAHul6zZde15UvoPbGb5aMm-KvtvROpqfB8/getUpdates "HTTP/1.1 409 Conflict"
ERROR:telegram.ext.Application:No error handlers are registered, logging exception.
Traceback (most recent call last):
  File "/Users/rexrealingojr./Library/CloudStorage/GoogleDrive-rex15realingo@gmail.com/My Drive/Ai/.venv/lib/python3.13/site-packages/telegram/ext/_utils/networkloop.py", line 115, in network_retry_loop
    if not await do_action():
           ^^^^^^^^^^^^^^^^^
  File "/Users/rexrealingojr./Library/CloudStorage/GoogleDrive-rex15realingo@gmail.com/My Drive/Ai/.venv/lib/python3.13/site-packages/telegram/ext/_utils/networkloop.py", line 108, in do_action
    return action_cb_task.result()
           ~~~~~~~~~~~~~~~~~~~~~^^
  File "/Users/rexrealingojr./Library/CloudStorage/GoogleDrive-rex15realingo@gmail.com/My Drive/Ai/.venv/lib/python3.13/site-packages/telegram/ext/_updater.py", line 340, in polling_action_cb
    updates = await self.bot.get_updates(
              ^^^^^^^^^^^^^^^^^^^^^^^^^^^
    ...<3 lines>...
    )
    ^
  File "/Users/rexrealingojr./Library/CloudStorage/GoogleDrive-rex15realingo@gmail.com/My Drive/Ai/.venv/lib/python3.13/site-packages/telegram/ext/_extbot.py", line 669, in get_updates
    updates = await super().get_updates(
              ^^^^^^^^^^^^^^^^^^^^^^^^^^
    ...<9 lines>...
    )
    ^
  File "/Users/rexrealingojr./Library/CloudStorage/GoogleDrive-rex15realingo@gmail.com/My Drive/Ai/.venv/lib/python3.13/site-packages/telegram/_bot.py", line 4610, in get_updates
    await self._post(
    ^^^^^^^^^^^^^^^^^
    ...<7 lines>...
    ),
    ^
  File "/Users/rexrealingojr./Library/CloudStorage/GoogleDrive-rex15realingo@gmail.com/My Drive/Ai/.venv/lib/python3.13/site-packages/telegram/_bot.py", line 697, in _post
    return await self._do_post(
           ^^^^^^^^^^^^^^^^^^^^
    ...<6 lines>...
    )
    ^
  File "/Users/rexrealingojr./Library/CloudStorage/GoogleDrive-rex15realingo@gmail.com/My Drive/Ai/.venv/lib/python3.13/site-packages/telegram/ext/_extbot.py", line 369, in _do_post
    return await super()._do_post(
           ^^^^^^^^^^^^^^^^^^^^^^^
    ...<6 lines>...
    )
    ^
  File "/Users/rexrealingojr./Library/CloudStorage/GoogleDrive-rex15realingo@gmail.com/My Drive/Ai/.venv/lib/python3.13/site-packages/telegram/_bot.py", line 726, in _do_post
    result = await request.post(
             ^^^^^^^^^^^^^^^^^^^
    ...<6 lines>...
    )
    ^
  File "/Users/rexrealingojr./Library/CloudStorage/GoogleDrive-rex15realingo@gmail.com/My Drive/Ai/.venv/lib/python3.13/site-packages/telegram/request/_baserequest.py", line 197, in post
    result = await self._request_wrapper(
             ^^^^^^^^^^^^^^^^^^^^^^^^^^^^
    ...<7 lines>...
    )
    ^
  File "/Users/rexrealingojr./Library/CloudStorage/GoogleDrive-rex15realingo@gmail.com/My Drive/Ai/.venv/lib/python3.13/site-packages/telegram/request/_baserequest.py", line 374, in _request_wrapper
    raise exception
telegram.error.Conflict: Conflict: terminated by other getUpdates request; make sure that only one bot instance is running
INFO:httpx:HTTP Request: POST https://api.telegram.org/bot7779786808:AAHul6zZde15UvoPbGb5aMm-KvtvROpqfB8/getUpdates "HTTP/1.1 200 OK"
INFO:httpx:HTTP Request: POST https://api.telegram.org/bot7779786808:AAHul6zZde15UvoPbGb5aMm-KvtvROpqfB8/getUpdates "HTTP/1.1 200 OK"
INFO:httpx:HTTP Request: POST https://api.telegram.org/bot7779786808:AAHul6zZde15UvoPbGb5aMm-KvtvROpqfB8/getUpdates "HTTP/1.1 409 Conflict"
ERROR:telegram.ext.Application:No error handlers are registered, logging exception.
Traceback (most recent call last):
  File "/Users/rexrealingojr./Library/CloudStorage/GoogleDrive-rex15realingo@gmail.com/My Drive/Ai/.venv/lib/python3.13/site-packages/telegram/ext/_utils/networkloop.py", line 115, in network_retry_loop
    if not await do_action():
           ^^^^^^^^^^^^^^^^^
  File "/Users/rexrealingojr./Library/CloudStorage/GoogleDrive-rex15realingo@gmail.com/My Drive/Ai/.venv/lib/python3.13/site-packages/telegram/ext/_utils/networkloop.py", line 108, in do_action
    return action_cb_task.result()
           ~~~~~~~~~~~~~~~~~~~~~^^
  File "/Users/rexrealingojr./Library/CloudStorage/GoogleDrive-rex15realingo@gmail.com/My Drive/Ai/.venv/lib/python3.13/site-packages/telegram/ext/_updater.py", line 340, in polling_action_cb
    updates = await self.bot.get_updates(
              ^^^^^^^^^^^^^^^^^^^^^^^^^^^
    ...<3 lines>...
    )
    ^
  File "/Users/rexrealingojr./Library/CloudStorage/GoogleDrive-rex15realingo@gmail.com/My Drive/Ai/.venv/lib/python3.13/site-packages/telegram/ext/_extbot.py", line 669, in get_updates
    updates = await super().get_updates(
              ^^^^^^^^^^^^^^^^^^^^^^^^^^
    ...<9 lines>...
    )
    ^
  File "/Users/rexrealingojr./Library/CloudStorage/GoogleDrive-rex15realingo@gmail.com/My Drive/Ai/.venv/lib/python3.13/site-packages/telegram/_bot.py", line 4610, in get_updates
    await self._post(
    ^^^^^^^^^^^^^^^^^
    ...<7 lines>...
    ),
    ^
  File "/Users/rexrealingojr./Library/CloudStorage/GoogleDrive-rex15realingo@gmail.com/My Drive/Ai/.venv/lib/python3.13/site-packages/telegram/_bot.py", line 697, in _post
    return await self._do_post(
           ^^^^^^^^^^^^^^^^^^^^
    ...<6 lines>...
    )
    ^
  File "/Users/rexrealingojr./Library/CloudStorage/GoogleDrive-rex15realingo@gmail.com/My Drive/Ai/.venv/lib/python3.13/site-packages/telegram/ext/_extbot.py", line 369, in _do_post
    return await super()._do_post(
           ^^^^^^^^^^^^^^^^^^^^^^^
    ...<6 lines>...
    )
    ^
  File "/Users/rexrealingojr./Library/CloudStorage/GoogleDrive-rex15realingo@gmail.com/My Drive/Ai/.venv/lib/python3.13/site-packages/telegram/_bot.py", line 726, in _do_post
    result = await request.post(
             ^^^^^^^^^^^^^^^^^^^
    ...<6 lines>...
    )
    ^
  File "/Users/rexrealingojr./Library/CloudStorage/GoogleDrive-rex15realingo@gmail.com/My Drive/Ai/.venv/lib/python3.13/site-packages/telegram/request/_baserequest.py", line 197, in post
    result = await self._request_wrapper(
             ^^^^^^^^^^^^^^^^^^^^^^^^^^^^
    ...<7 lines>...
    )
    ^
  File "/Users/rexrealingojr./Library/CloudStorage/GoogleDrive-rex15realingo@gmail.com/My Drive/Ai/.venv/lib/python3.13/site-packages/telegram/request/_baserequest.py", line 374, in _request_wrapper
    raise exception
telegram.error.Conflict: Conflict: terminated by other getUpdates request; make sure that only one bot instance is running
INFO:httpx:HTTP Request: POST https://api.telegram.org/bot7779786808:AAHul6zZde15UvoPbGb5aMm-KvtvROpqfB8/getUpdates "HTTP/1.1 200 OK"
INFO:httpx:HTTP Request: POST https://api.telegram.org/bot7779786808:AAHul6zZde15UvoPbGb5aMm-KvtvROpqfB8/getUpdates "HTTP/1.1 200 OK"
INFO:httpx:HTTP Request: POST https://api.telegram.org/bot7779786808:AAHul6zZde15UvoPbGb5aMm-KvtvROpqfB8/getUpdates "HTTP/1.1 200 OK"
ERROR:telegram.ext.Application:No error handlers are registered, logging exception.
Traceback (most recent call last):
  File "/Users/rexrealingojr./Library/CloudStorage/GoogleDrive-rex15realingo@gmail.com/My Drive/Ai/.venv/lib/python3.13/site-packages/telegram/ext/_application.py", line 1309, in process_update
    await coroutine
  File "/Users/rexrealingojr./Library/CloudStorage/GoogleDrive-rex15realingo@gmail.com/My Drive/Ai/.venv/lib/python3.13/site-packages/telegram/ext/_handlers/basehandler.py", line 158, in handle_update
    return await self.callback(update, context)
           ^^^^^^^^^^^^^^^^^^^^^^^^^^^^^^^^^^^^
  File "/Users/rexrealingojr./Library/CloudStorage/GoogleDrive-rex15realingo@gmail.com/My Drive/Ai/handlers/commands.py", line 27, in menu_command
    await update.message.reply_text("üè† Here's our main menu:", reply_markup=InlineKeyboardMarkup(keyboard))
                                                                             ~~~~~~~~~~~~~~~~~~~~^^^^^^^^^^
  File "/Users/rexrealingojr./Library/CloudStorage/GoogleDrive-rex15realingo@gmail.com/My Drive/Ai/.venv/lib/python3.13/site-packages/telegram/_inline/inlinekeyboardmarkup.py", line 80, in __init__
    raise ValueError(
    ...<2 lines>...
    )
ValueError: The parameter `inline_keyboard` should be a sequence of sequences of InlineKeyboardButtons
INFO:httpx:HTTP Request: POST https://api.telegram.org/bot7779786808:AAHul6zZde15UvoPbGb5aMm-KvtvROpqfB8/getUpdates "HTTP/1.1 200 OK"
INFO:httpx:HTTP Request: POST https://api.telegram.org/bot7779786808:AAHul6zZde15UvoPbGb5aMm-KvtvROpqfB8/getUpdates "HTTP/1.1 200 OK"
INFO:httpx:HTTP Request: POST https://api.telegram.org/bot7779786808:AAHul6zZde15UvoPbGb5aMm-KvtvROpqfB8/sendMessage "HTTP/1.1 200 OK"
ERROR:telegram.ext.Application:No error handlers are registered, logging exception.
Traceback (most recent call last):
  File "/Users/rexrealingojr./Library/CloudStorage/GoogleDrive-rex15realingo@gmail.com/My Drive/Ai/.venv/lib/python3.13/site-packages/telegram/ext/_application.py", line 1309, in process_update
    await coroutine
  File "/Users/rexrealingojr./Library/CloudStorage/GoogleDrive-rex15realingo@gmail.com/My Drive/Ai/.venv/lib/python3.13/site-packages/telegram/ext/_handlers/basehandler.py", line 158, in handle_update
    return await self.callback(update, context)
           ^^^^^^^^^^^^^^^^^^^^^^^^^^^^^^^^^^^^
  File "/Users/rexrealingojr./Library/CloudStorage/GoogleDrive-rex15realingo@gmail.com/My Drive/Ai/handlers/commands.py", line 13, in start_command
    await menu_command(update, context)
  File "/Users/rexrealingojr./Library/CloudStorage/GoogleDrive-rex15realingo@gmail.com/My Drive/Ai/handlers/commands.py", line 27, in menu_command
    await update.message.reply_text("üè† Here's our main menu:", reply_markup=InlineKeyboardMarkup(keyboard))
                                                                             ~~~~~~~~~~~~~~~~~~~~^^^^^^^^^^
  File "/Users/rexrealingojr./Library/CloudStorage/GoogleDrive-rex15realingo@gmail.com/My Drive/Ai/.venv/lib/python3.13/site-packages/telegram/_inline/inlinekeyboardmarkup.py", line 80, in __init__
    raise ValueError(
    ...<2 lines>...
    )
ValueError: The parameter `inline_keyboard` should be a sequence of sequences of InlineKeyboardButtons
INFO:httpx:HTTP Request: POST https://api.telegram.org/bot7779786808:AAHul6zZde15UvoPbGb5aMm-KvtvROpqfB8/getUpdates "HTTP/1.1 409 Conflict"
ERROR:telegram.ext.Application:No error handlers are registered, logging exception.
Traceback (most recent call last):
  File "/Users/rexrealingojr./Library/CloudStorage/GoogleDrive-rex15realingo@gmail.com/My Drive/Ai/.venv/lib/python3.13/site-packages/telegram/ext/_utils/networkloop.py", line 115, in network_retry_loop
    if not await do_action():
           ^^^^^^^^^^^^^^^^^
  File "/Users/rexrealingojr./Library/CloudStorage/GoogleDrive-rex15realingo@gmail.com/My Drive/Ai/.venv/lib/python3.13/site-packages/telegram/ext/_utils/networkloop.py", line 108, in do_action
    return action_cb_task.result()
           ~~~~~~~~~~~~~~~~~~~~~^^
  File "/Users/rexrealingojr./Library/CloudStorage/GoogleDrive-rex15realingo@gmail.com/My Drive/Ai/.venv/lib/python3.13/site-packages/telegram/ext/_updater.py", line 340, in polling_action_cb
    updates = await self.bot.get_updates(
              ^^^^^^^^^^^^^^^^^^^^^^^^^^^
    ...<3 lines>...
    )
    ^
  File "/Users/rexrealingojr./Library/CloudStorage/GoogleDrive-rex15realingo@gmail.com/My Drive/Ai/.venv/lib/python3.13/site-packages/telegram/ext/_extbot.py", line 669, in get_updates
    updates = await super().get_updates(
              ^^^^^^^^^^^^^^^^^^^^^^^^^^
    ...<9 lines>...
    )
    ^
  File "/Users/rexrealingojr./Library/CloudStorage/GoogleDrive-rex15realingo@gmail.com/My Drive/Ai/.venv/lib/python3.13/site-packages/telegram/_bot.py", line 4610, in get_updates
    await self._post(
    ^^^^^^^^^^^^^^^^^
    ...<7 lines>...
    ),
    ^
  File "/Users/rexrealingojr./Library/CloudStorage/GoogleDrive-rex15realingo@gmail.com/My Drive/Ai/.venv/lib/python3.13/site-packages/telegram/_bot.py", line 697, in _post
    return await self._do_post(
           ^^^^^^^^^^^^^^^^^^^^
    ...<6 lines>...
    )
    ^
  File "/Users/rexrealingojr./Library/CloudStorage/GoogleDrive-rex15realingo@gmail.com/My Drive/Ai/.venv/lib/python3.13/site-packages/telegram/ext/_extbot.py", line 369, in _do_post
    return await super()._do_post(
           ^^^^^^^^^^^^^^^^^^^^^^^
    ...<6 lines>...
    )
    ^
  File "/Users/rexrealingojr./Library/CloudStorage/GoogleDrive-rex15realingo@gmail.com/My Drive/Ai/.venv/lib/python3.13/site-packages/telegram/_bot.py", line 726, in _do_post
    result = await request.post(
             ^^^^^^^^^^^^^^^^^^^
    ...<6 lines>...
    )
    ^
  File "/Users/rexrealingojr./Library/CloudStorage/GoogleDrive-rex15realingo@gmail.com/My Drive/Ai/.venv/lib/python3.13/site-packages/telegram/request/_baserequest.py", line 197, in post
    result = await self._request_wrapper(
             ^^^^^^^^^^^^^^^^^^^^^^^^^^^^
    ...<7 lines>...
    )
    ^
  File "/Users/rexrealingojr./Library/CloudStorage/GoogleDrive-rex15realingo@gmail.com/My Drive/Ai/.venv/lib/python3.13/site-packages/telegram/request/_baserequest.py", line 374, in _request_wrapper
    raise exception
telegram.error.Conflict: Conflict: terminated by other getUpdates request; make sure that only one bot instance is running
INFO:httpx:HTTP Request: POST https://api.telegram.org/bot7779786808:AAHul6zZde15UvoPbGb5aMm-KvtvROpqfB8/getUpdates "HTTP/1.1 200 OK"
ERROR:telegram.ext.Application:No error handlers are registered, logging exception.
Traceback (most recent call last):
  File "/Users/rexrealingojr./Library/CloudStorage/GoogleDrive-rex15realingo@gmail.com/My Drive/Ai/.venv/lib/python3.13/site-packages/telegram/ext/_application.py", line 1309, in process_update
    await coroutine
  File "/Users/rexrealingojr./Library/CloudStorage/GoogleDrive-rex15realingo@gmail.com/My Drive/Ai/.venv/lib/python3.13/site-packages/telegram/ext/_handlers/basehandler.py", line 158, in handle_update
    return await self.callback(update, context)
           ^^^^^^^^^^^^^^^^^^^^^^^^^^^^^^^^^^^^
  File "/Users/rexrealingojr./Library/CloudStorage/GoogleDrive-rex15realingo@gmail.com/My Drive/Ai/handlers/commands.py", line 27, in menu_command
    await update.message.reply_text("üè† Here's our main menu:", reply_markup=InlineKeyboardMarkup(keyboard))
                                                                             ~~~~~~~~~~~~~~~~~~~~^^^^^^^^^^
  File "/Users/rexrealingojr./Library/CloudStorage/GoogleDrive-rex15realingo@gmail.com/My Drive/Ai/.venv/lib/python3.13/site-packages/telegram/_inline/inlinekeyboardmarkup.py", line 80, in __init__
    raise ValueError(
    ...<2 lines>...
    )
ValueError: The parameter `inline_keyboard` should be a sequence of sequences of InlineKeyboardButtons
INFO:httpx:HTTP Request: POST https://api.telegram.org/bot7779786808:AAHul6zZde15UvoPbGb5aMm-KvtvROpqfB8/sendMessage "HTTP/1.1 200 OK"
ERROR:telegram.ext.Application:No error handlers are registered, logging exception.
Traceback (most recent call last):
  File "/Users/rexrealingojr./Library/CloudStorage/GoogleDrive-rex15realingo@gmail.com/My Drive/Ai/.venv/lib/python3.13/site-packages/telegram/ext/_application.py", line 1309, in process_update
    await coroutine
  File "/Users/rexrealingojr./Library/CloudStorage/GoogleDrive-rex15realingo@gmail.com/My Drive/Ai/.venv/lib/python3.13/site-packages/telegram/ext/_handlers/basehandler.py", line 158, in handle_update
    return await self.callback(update, context)
           ^^^^^^^^^^^^^^^^^^^^^^^^^^^^^^^^^^^^
  File "/Users/rexrealingojr./Library/CloudStorage/GoogleDrive-rex15realingo@gmail.com/My Drive/Ai/handlers/commands.py", line 13, in start_command
    await menu_command(update, context)
  File "/Users/rexrealingojr./Library/CloudStorage/GoogleDrive-rex15realingo@gmail.com/My Drive/Ai/handlers/commands.py", line 27, in menu_command
    await update.message.reply_text("üè† Here's our main menu:", reply_markup=InlineKeyboardMarkup(keyboard))
                                                                             ~~~~~~~~~~~~~~~~~~~~^^^^^^^^^^
  File "/Users/rexrealingojr./Library/CloudStorage/GoogleDrive-rex15realingo@gmail.com/My Drive/Ai/.venv/lib/python3.13/site-packages/telegram/_inline/inlinekeyboardmarkup.py", line 80, in __init__
    raise ValueError(
    ...<2 lines>...
    )
ValueError: The parameter `inline_keyboard` should be a sequence of sequences of InlineKeyboardButtons
INFO:httpx:HTTP Request: POST https://api.telegram.org/bot7779786808:AAHul6zZde15UvoPbGb5aMm-KvtvROpqfB8/getUpdates "HTTP/1.1 409 Conflict"
ERROR:telegram.ext.Application:No error handlers are registered, logging exception.
Traceback (most recent call last):
  File "/Users/rexrealingojr./Library/CloudStorage/GoogleDrive-rex15realingo@gmail.com/My Drive/Ai/.venv/lib/python3.13/site-packages/telegram/ext/_utils/networkloop.py", line 115, in network_retry_loop
    if not await do_action():
           ^^^^^^^^^^^^^^^^^
  File "/Users/rexrealingojr./Library/CloudStorage/GoogleDrive-rex15realingo@gmail.com/My Drive/Ai/.venv/lib/python3.13/site-packages/telegram/ext/_utils/networkloop.py", line 108, in do_action
    return action_cb_task.result()
           ~~~~~~~~~~~~~~~~~~~~~^^
  File "/Users/rexrealingojr./Library/CloudStorage/GoogleDrive-rex15realingo@gmail.com/My Drive/Ai/.venv/lib/python3.13/site-packages/telegram/ext/_updater.py", line 340, in polling_action_cb
    updates = await self.bot.get_updates(
              ^^^^^^^^^^^^^^^^^^^^^^^^^^^
    ...<3 lines>...
    )
    ^
  File "/Users/rexrealingojr./Library/CloudStorage/GoogleDrive-rex15realingo@gmail.com/My Drive/Ai/.venv/lib/python3.13/site-packages/telegram/ext/_extbot.py", line 669, in get_updates
    updates = await super().get_updates(
              ^^^^^^^^^^^^^^^^^^^^^^^^^^
    ...<9 lines>...
    )
    ^
  File "/Users/rexrealingojr./Library/CloudStorage/GoogleDrive-rex15realingo@gmail.com/My Drive/Ai/.venv/lib/python3.13/site-packages/telegram/_bot.py", line 4610, in get_updates
    await self._post(
    ^^^^^^^^^^^^^^^^^
    ...<7 lines>...
    ),
    ^
  File "/Users/rexrealingojr./Library/CloudStorage/GoogleDrive-rex15realingo@gmail.com/My Drive/Ai/.venv/lib/python3.13/site-packages/telegram/_bot.py", line 697, in _post
    return await self._do_post(
           ^^^^^^^^^^^^^^^^^^^^
    ...<6 lines>...
    )
    ^
  File "/Users/rexrealingojr./Library/CloudStorage/GoogleDrive-rex15realingo@gmail.com/My Drive/Ai/.venv/lib/python3.13/site-packages/telegram/ext/_extbot.py", line 369, in _do_post
    return await super()._do_post(
           ^^^^^^^^^^^^^^^^^^^^^^^
    ...<6 lines>...
    )
    ^
  File "/Users/rexrealingojr./Library/CloudStorage/GoogleDrive-rex15realingo@gmail.com/My Drive/Ai/.venv/lib/python3.13/site-packages/telegram/_bot.py", line 726, in _do_post
    result = await request.post(
             ^^^^^^^^^^^^^^^^^^^
    ...<6 lines>...
    )
    ^
  File "/Users/rexrealingojr./Library/CloudStorage/GoogleDrive-rex15realingo@gmail.com/My Drive/Ai/.venv/lib/python3.13/site-packages/telegram/request/_baserequest.py", line 197, in post
    result = await self._request_wrapper(
             ^^^^^^^^^^^^^^^^^^^^^^^^^^^^
    ...<7 lines>...
    )
    ^
  File "/Users/rexrealingojr./Library/CloudStorage/GoogleDrive-rex15realingo@gmail.com/My Drive/Ai/.venv/lib/python3.13/site-packages/telegram/request/_baserequest.py", line 374, in _request_wrapper
    raise exception
telegram.error.Conflict: Conflict: terminated by other getUpdates request; make sure that only one bot instance is running
INFO:httpx:HTTP Request: POST https://api.telegram.org/bot7779786808:AAHul6zZde15UvoPbGb5aMm-KvtvROpqfB8/getUpdates "HTTP/1.1 409 Conflict"
ERROR:telegram.ext.Application:No error handlers are registered, logging exception.
Traceback (most recent call last):
  File "/Users/rexrealingojr./Library/CloudStorage/GoogleDrive-rex15realingo@gmail.com/My Drive/Ai/.venv/lib/python3.13/site-packages/telegram/ext/_utils/networkloop.py", line 115, in network_retry_loop
    if not await do_action():
           ^^^^^^^^^^^^^^^^^
  File "/Users/rexrealingojr./Library/CloudStorage/GoogleDrive-rex15realingo@gmail.com/My Drive/Ai/.venv/lib/python3.13/site-packages/telegram/ext/_utils/networkloop.py", line 108, in do_action
    return action_cb_task.result()
           ~~~~~~~~~~~~~~~~~~~~~^^
  File "/Users/rexrealingojr./Library/CloudStorage/GoogleDrive-rex15realingo@gmail.com/My Drive/Ai/.venv/lib/python3.13/site-packages/telegram/ext/_updater.py", line 340, in polling_action_cb
    updates = await self.bot.get_updates(
              ^^^^^^^^^^^^^^^^^^^^^^^^^^^
    ...<3 lines>...
    )
    ^
  File "/Users/rexrealingojr./Library/CloudStorage/GoogleDrive-rex15realingo@gmail.com/My Drive/Ai/.venv/lib/python3.13/site-packages/telegram/ext/_extbot.py", line 669, in get_updates
    updates = await super().get_updates(
              ^^^^^^^^^^^^^^^^^^^^^^^^^^
    ...<9 lines>...
    )
    ^
  File "/Users/rexrealingojr./Library/CloudStorage/GoogleDrive-rex15realingo@gmail.com/My Drive/Ai/.venv/lib/python3.13/site-packages/telegram/_bot.py", line 4610, in get_updates
    await self._post(
    ^^^^^^^^^^^^^^^^^
    ...<7 lines>...
    ),
    ^
  File "/Users/rexrealingojr./Library/CloudStorage/GoogleDrive-rex15realingo@gmail.com/My Drive/Ai/.venv/lib/python3.13/site-packages/telegram/_bot.py", line 697, in _post
    return await self._do_post(
           ^^^^^^^^^^^^^^^^^^^^
    ...<6 lines>...
    )
    ^
  File "/Users/rexrealingojr./Library/CloudStorage/GoogleDrive-rex15realingo@gmail.com/My Drive/Ai/.venv/lib/python3.13/site-packages/telegram/ext/_extbot.py", line 369, in _do_post
    return await super()._do_post(
           ^^^^^^^^^^^^^^^^^^^^^^^
    ...<6 lines>...
    )
    ^
  File "/Users/rexrealingojr./Library/CloudStorage/GoogleDrive-rex15realingo@gmail.com/My Drive/Ai/.venv/lib/python3.13/site-packages/telegram/_bot.py", line 726, in _do_post
    result = await request.post(
             ^^^^^^^^^^^^^^^^^^^
    ...<6 lines>...
    )
    ^
  File "/Users/rexrealingojr./Library/CloudStorage/GoogleDrive-rex15realingo@gmail.com/My Drive/Ai/.venv/lib/python3.13/site-packages/telegram/request/_baserequest.py", line 197, in post
    result = await self._request_wrapper(
             ^^^^^^^^^^^^^^^^^^^^^^^^^^^^
    ...<7 lines>...
    )
    ^
  File "/Users/rexrealingojr./Library/CloudStorage/GoogleDrive-rex15realingo@gmail.com/My Drive/Ai/.venv/lib/python3.13/site-packages/telegram/request/_baserequest.py", line 374, in _request_wrapper
    raise exception
telegram.error.Conflict: Conflict: terminated by other getUpdates request; make sure that only one bot instance is running
INFO:httpx:HTTP Request: POST https://api.telegram.org/bot7779786808:AAHul6zZde15UvoPbGb5aMm-KvtvROpqfB8/getUpdates "HTTP/1.1 409 Conflict"
ERROR:telegram.ext.Application:No error handlers are registered, logging exception.
Traceback (most recent call last):
  File "/Users/rexrealingojr./Library/CloudStorage/GoogleDrive-rex15realingo@gmail.com/My Drive/Ai/.venv/lib/python3.13/site-packages/telegram/ext/_utils/networkloop.py", line 115, in network_retry_loop
    if not await do_action():
           ^^^^^^^^^^^^^^^^^
  File "/Users/rexrealingojr./Library/CloudStorage/GoogleDrive-rex15realingo@gmail.com/My Drive/Ai/.venv/lib/python3.13/site-packages/telegram/ext/_utils/networkloop.py", line 108, in do_action
    return action_cb_task.result()
           ~~~~~~~~~~~~~~~~~~~~~^^
  File "/Users/rexrealingojr./Library/CloudStorage/GoogleDrive-rex15realingo@gmail.com/My Drive/Ai/.venv/lib/python3.13/site-packages/telegram/ext/_updater.py", line 340, in polling_action_cb
    updates = await self.bot.get_updates(
              ^^^^^^^^^^^^^^^^^^^^^^^^^^^
    ...<3 lines>...
    )
    ^
  File "/Users/rexrealingojr./Library/CloudStorage/GoogleDrive-rex15realingo@gmail.com/My Drive/Ai/.venv/lib/python3.13/site-packages/telegram/ext/_extbot.py", line 669, in get_updates
    updates = await super().get_updates(
              ^^^^^^^^^^^^^^^^^^^^^^^^^^
    ...<9 lines>...
    )
    ^
  File "/Users/rexrealingojr./Library/CloudStorage/GoogleDrive-rex15realingo@gmail.com/My Drive/Ai/.venv/lib/python3.13/site-packages/telegram/_bot.py", line 4610, in get_updates
    await self._post(
    ^^^^^^^^^^^^^^^^^
    ...<7 lines>...
    ),
    ^
  File "/Users/rexrealingojr./Library/CloudStorage/GoogleDrive-rex15realingo@gmail.com/My Drive/Ai/.venv/lib/python3.13/site-packages/telegram/_bot.py", line 697, in _post
    return await self._do_post(
           ^^^^^^^^^^^^^^^^^^^^
    ...<6 lines>...
    )
    ^
  File "/Users/rexrealingojr./Library/CloudStorage/GoogleDrive-rex15realingo@gmail.com/My Drive/Ai/.venv/lib/python3.13/site-packages/telegram/ext/_extbot.py", line 369, in _do_post
    return await super()._do_post(
           ^^^^^^^^^^^^^^^^^^^^^^^
    ...<6 lines>...
    )
    ^
  File "/Users/rexrealingojr./Library/CloudStorage/GoogleDrive-rex15realingo@gmail.com/My Drive/Ai/.venv/lib/python3.13/site-packages/telegram/_bot.py", line 726, in _do_post
    result = await request.post(
             ^^^^^^^^^^^^^^^^^^^
    ...<6 lines>...
    )
    ^
  File "/Users/rexrealingojr./Library/CloudStorage/GoogleDrive-rex15realingo@gmail.com/My Drive/Ai/.venv/lib/python3.13/site-packages/telegram/request/_baserequest.py", line 197, in post
    result = await self._request_wrapper(
             ^^^^^^^^^^^^^^^^^^^^^^^^^^^^
    ...<7 lines>...
    )
    ^
  File "/Users/rexrealingojr./Library/CloudStorage/GoogleDrive-rex15realingo@gmail.com/My Drive/Ai/.venv/lib/python3.13/site-packages/telegram/request/_baserequest.py", line 374, in _request_wrapper
    raise exception
telegram.error.Conflict: Conflict: terminated by other getUpdates request; make sure that only one bot instance is running
INFO:httpx:HTTP Request: POST https://api.telegram.org/bot7779786808:AAHul6zZde15UvoPbGb5aMm-KvtvROpqfB8/getUpdates "HTTP/1.1 200 OK"
INFO:httpx:HTTP Request: POST https://api.telegram.org/bot7779786808:AAHul6zZde15UvoPbGb5aMm-KvtvROpqfB8/sendMessage "HTTP/1.1 200 OK"
ERROR:telegram.ext.Application:No error handlers are registered, logging exception.
Traceback (most recent call last):
  File "/Users/rexrealingojr./Library/CloudStorage/GoogleDrive-rex15realingo@gmail.com/My Drive/Ai/.venv/lib/python3.13/site-packages/telegram/ext/_application.py", line 1309, in process_update
    await coroutine
  File "/Users/rexrealingojr./Library/CloudStorage/GoogleDrive-rex15realingo@gmail.com/My Drive/Ai/.venv/lib/python3.13/site-packages/telegram/ext/_handlers/basehandler.py", line 158, in handle_update
    return await self.callback(update, context)
           ^^^^^^^^^^^^^^^^^^^^^^^^^^^^^^^^^^^^
  File "/Users/rexrealingojr./Library/CloudStorage/GoogleDrive-rex15realingo@gmail.com/My Drive/Ai/handlers/commands.py", line 13, in start_command
    await menu_command(update, context)
  File "/Users/rexrealingojr./Library/CloudStorage/GoogleDrive-rex15realingo@gmail.com/My Drive/Ai/handlers/commands.py", line 27, in menu_command
    await update.message.reply_text("üè† Here's our main menu:", reply_markup=InlineKeyboardMarkup(keyboard))
                                                                             ~~~~~~~~~~~~~~~~~~~~^^^^^^^^^^
  File "/Users/rexrealingojr./Library/CloudStorage/GoogleDrive-rex15realingo@gmail.com/My Drive/Ai/.venv/lib/python3.13/site-packages/telegram/_inline/inlinekeyboardmarkup.py", line 80, in __init__
    raise ValueError(
    ...<2 lines>...
    )
ValueError: The parameter `inline_keyboard` should be a sequence of sequences of InlineKeyboardButtons
INFO:httpx:HTTP Request: POST https://api.telegram.org/bot7779786808:AAHul6zZde15UvoPbGb5aMm-KvtvROpqfB8/getUpdates "HTTP/1.1 409 Conflict"
ERROR:telegram.ext.Application:No error handlers are registered, logging exception.
Traceback (most recent call last):
  File "/Users/rexrealingojr./Library/CloudStorage/GoogleDrive-rex15realingo@gmail.com/My Drive/Ai/.venv/lib/python3.13/site-packages/telegram/ext/_utils/networkloop.py", line 115, in network_retry_loop
    if not await do_action():
           ^^^^^^^^^^^^^^^^^
  File "/Users/rexrealingojr./Library/CloudStorage/GoogleDrive-rex15realingo@gmail.com/My Drive/Ai/.venv/lib/python3.13/site-packages/telegram/ext/_utils/networkloop.py", line 108, in do_action
    return action_cb_task.result()
           ~~~~~~~~~~~~~~~~~~~~~^^
  File "/Users/rexrealingojr./Library/CloudStorage/GoogleDrive-rex15realingo@gmail.com/My Drive/Ai/.venv/lib/python3.13/site-packages/telegram/ext/_updater.py", line 340, in polling_action_cb
    updates = await self.bot.get_updates(
              ^^^^^^^^^^^^^^^^^^^^^^^^^^^
    ...<3 lines>...
    )
    ^
  File "/Users/rexrealingojr./Library/CloudStorage/GoogleDrive-rex15realingo@gmail.com/My Drive/Ai/.venv/lib/python3.13/site-packages/telegram/ext/_extbot.py", line 669, in get_updates
    updates = await super().get_updates(
              ^^^^^^^^^^^^^^^^^^^^^^^^^^
    ...<9 lines>...
    )
    ^
  File "/Users/rexrealingojr./Library/CloudStorage/GoogleDrive-rex15realingo@gmail.com/My Drive/Ai/.venv/lib/python3.13/site-packages/telegram/_bot.py", line 4610, in get_updates
    await self._post(
    ^^^^^^^^^^^^^^^^^
    ...<7 lines>...
    ),
    ^
  File "/Users/rexrealingojr./Library/CloudStorage/GoogleDrive-rex15realingo@gmail.com/My Drive/Ai/.venv/lib/python3.13/site-packages/telegram/_bot.py", line 697, in _post
    return await self._do_post(
           ^^^^^^^^^^^^^^^^^^^^
    ...<6 lines>...
    )
    ^
  File "/Users/rexrealingojr./Library/CloudStorage/GoogleDrive-rex15realingo@gmail.com/My Drive/Ai/.venv/lib/python3.13/site-packages/telegram/ext/_extbot.py", line 369, in _do_post
    return await super()._do_post(
           ^^^^^^^^^^^^^^^^^^^^^^^
    ...<6 lines>...
    )
    ^
  File "/Users/rexrealingojr./Library/CloudStorage/GoogleDrive-rex15realingo@gmail.com/My Drive/Ai/.venv/lib/python3.13/site-packages/telegram/_bot.py", line 726, in _do_post
    result = await request.post(
             ^^^^^^^^^^^^^^^^^^^
    ...<6 lines>...
    )
    ^
  File "/Users/rexrealingojr./Library/CloudStorage/GoogleDrive-rex15realingo@gmail.com/My Drive/Ai/.venv/lib/python3.13/site-packages/telegram/request/_baserequest.py", line 197, in post
    result = await self._request_wrapper(
             ^^^^^^^^^^^^^^^^^^^^^^^^^^^^
    ...<7 lines>...
    )
    ^
  File "/Users/rexrealingojr./Library/CloudStorage/GoogleDrive-rex15realingo@gmail.com/My Drive/Ai/.venv/lib/python3.13/site-packages/telegram/request/_baserequest.py", line 374, in _request_wrapper
    raise exception
telegram.error.Conflict: Conflict: terminated by other getUpdates request; make sure that only one bot instance is running
INFO:httpx:HTTP Request: POST https://api.telegram.org/bot7779786808:AAHul6zZde15UvoPbGb5aMm-KvtvROpqfB8/getUpdates "HTTP/1.1 409 Conflict"
ERROR:telegram.ext.Application:No error handlers are registered, logging exception.
Traceback (most recent call last):
  File "/Users/rexrealingojr./Library/CloudStorage/GoogleDrive-rex15realingo@gmail.com/My Drive/Ai/.venv/lib/python3.13/site-packages/telegram/ext/_utils/networkloop.py", line 115, in network_retry_loop
    if not await do_action():
           ^^^^^^^^^^^^^^^^^
  File "/Users/rexrealingojr./Library/CloudStorage/GoogleDrive-rex15realingo@gmail.com/My Drive/Ai/.venv/lib/python3.13/site-packages/telegram/ext/_utils/networkloop.py", line 108, in do_action
    return action_cb_task.result()
           ~~~~~~~~~~~~~~~~~~~~~^^
  File "/Users/rexrealingojr./Library/CloudStorage/GoogleDrive-rex15realingo@gmail.com/My Drive/Ai/.venv/lib/python3.13/site-packages/telegram/ext/_updater.py", line 340, in polling_action_cb
    updates = await self.bot.get_updates(
              ^^^^^^^^^^^^^^^^^^^^^^^^^^^
    ...<3 lines>...
    )
    ^
  File "/Users/rexrealingojr./Library/CloudStorage/GoogleDrive-rex15realingo@gmail.com/My Drive/Ai/.venv/lib/python3.13/site-packages/telegram/ext/_extbot.py", line 669, in get_updates
    updates = await super().get_updates(
              ^^^^^^^^^^^^^^^^^^^^^^^^^^
    ...<9 lines>...
    )
    ^
  File "/Users/rexrealingojr./Library/CloudStorage/GoogleDrive-rex15realingo@gmail.com/My Drive/Ai/.venv/lib/python3.13/site-packages/telegram/_bot.py", line 4610, in get_updates
    await self._post(
    ^^^^^^^^^^^^^^^^^
    ...<7 lines>...
    ),
    ^
  File "/Users/rexrealingojr./Library/CloudStorage/GoogleDrive-rex15realingo@gmail.com/My Drive/Ai/.venv/lib/python3.13/site-packages/telegram/_bot.py", line 697, in _post
    return await self._do_post(
           ^^^^^^^^^^^^^^^^^^^^
    ...<6 lines>...
    )
    ^
  File "/Users/rexrealingojr./Library/CloudStorage/GoogleDrive-rex15realingo@gmail.com/My Drive/Ai/.venv/lib/python3.13/site-packages/telegram/ext/_extbot.py", line 369, in _do_post
    return await super()._do_post(
           ^^^^^^^^^^^^^^^^^^^^^^^
    ...<6 lines>...
    )
    ^
  File "/Users/rexrealingojr./Library/CloudStorage/GoogleDrive-rex15realingo@gmail.com/My Drive/Ai/.venv/lib/python3.13/site-packages/telegram/_bot.py", line 726, in _do_post
    result = await request.post(
             ^^^^^^^^^^^^^^^^^^^
    ...<6 lines>...
    )
    ^
  File "/Users/rexrealingojr./Library/CloudStorage/GoogleDrive-rex15realingo@gmail.com/My Drive/Ai/.venv/lib/python3.13/site-packages/telegram/request/_baserequest.py", line 197, in post
    result = await self._request_wrapper(
             ^^^^^^^^^^^^^^^^^^^^^^^^^^^^
    ...<7 lines>...
    )
    ^
  File "/Users/rexrealingojr./Library/CloudStorage/GoogleDrive-rex15realingo@gmail.com/My Drive/Ai/.venv/lib/python3.13/site-packages/telegram/request/_baserequest.py", line 374, in _request_wrapper
    raise exception
telegram.error.Conflict: Conflict: terminated by other getUpdates request; make sure that only one bot instance is running
INFO:httpx:HTTP Request: POST https://api.telegram.org/bot7779786808:AAHul6zZde15UvoPbGb5aMm-KvtvROpqfB8/getUpdates "HTTP/1.1 409 Conflict"
ERROR:telegram.ext.Application:No error handlers are registered, logging exception.
Traceback (most recent call last):
  File "/Users/rexrealingojr./Library/CloudStorage/GoogleDrive-rex15realingo@gmail.com/My Drive/Ai/.venv/lib/python3.13/site-packages/telegram/ext/_utils/networkloop.py", line 115, in network_retry_loop
    if not await do_action():
           ^^^^^^^^^^^^^^^^^
  File "/Users/rexrealingojr./Library/CloudStorage/GoogleDrive-rex15realingo@gmail.com/My Drive/Ai/.venv/lib/python3.13/site-packages/telegram/ext/_utils/networkloop.py", line 108, in do_action
    return action_cb_task.result()
           ~~~~~~~~~~~~~~~~~~~~~^^
  File "/Users/rexrealingojr./Library/CloudStorage/GoogleDrive-rex15realingo@gmail.com/My Drive/Ai/.venv/lib/python3.13/site-packages/telegram/ext/_updater.py", line 340, in polling_action_cb
    updates = await self.bot.get_updates(
              ^^^^^^^^^^^^^^^^^^^^^^^^^^^
    ...<3 lines>...
    )
    ^
  File "/Users/rexrealingojr./Library/CloudStorage/GoogleDrive-rex15realingo@gmail.com/My Drive/Ai/.venv/lib/python3.13/site-packages/telegram/ext/_extbot.py", line 669, in get_updates
    updates = await super().get_updates(
              ^^^^^^^^^^^^^^^^^^^^^^^^^^
    ...<9 lines>...
    )
    ^
  File "/Users/rexrealingojr./Library/CloudStorage/GoogleDrive-rex15realingo@gmail.com/My Drive/Ai/.venv/lib/python3.13/site-packages/telegram/_bot.py", line 4610, in get_updates
    await self._post(
    ^^^^^^^^^^^^^^^^^
    ...<7 lines>...
    ),
    ^
  File "/Users/rexrealingojr./Library/CloudStorage/GoogleDrive-rex15realingo@gmail.com/My Drive/Ai/.venv/lib/python3.13/site-packages/telegram/_bot.py", line 697, in _post
    return await self._do_post(
           ^^^^^^^^^^^^^^^^^^^^
    ...<6 lines>...
    )
    ^
  File "/Users/rexrealingojr./Library/CloudStorage/GoogleDrive-rex15realingo@gmail.com/My Drive/Ai/.venv/lib/python3.13/site-packages/telegram/ext/_extbot.py", line 369, in _do_post
    return await super()._do_post(
           ^^^^^^^^^^^^^^^^^^^^^^^
    ...<6 lines>...
    )
    ^
  File "/Users/rexrealingojr./Library/CloudStorage/GoogleDrive-rex15realingo@gmail.com/My Drive/Ai/.venv/lib/python3.13/site-packages/telegram/_bot.py", line 726, in _do_post
    result = await request.post(
             ^^^^^^^^^^^^^^^^^^^
    ...<6 lines>...
    )
    ^
  File "/Users/rexrealingojr./Library/CloudStorage/GoogleDrive-rex15realingo@gmail.com/My Drive/Ai/.venv/lib/python3.13/site-packages/telegram/request/_baserequest.py", line 197, in post
    result = await self._request_wrapper(
             ^^^^^^^^^^^^^^^^^^^^^^^^^^^^
    ...<7 lines>...
    )
    ^
  File "/Users/rexrealingojr./Library/CloudStorage/GoogleDrive-rex15realingo@gmail.com/My Drive/Ai/.venv/lib/python3.13/site-packages/telegram/request/_baserequest.py", line 374, in _request_wrapper
    raise exception
telegram.error.Conflict: Conflict: terminated by other getUpdates request; make sure that only one bot instance is running
INFO:httpx:HTTP Request: POST https://api.telegram.org/bot7779786808:AAHul6zZde15UvoPbGb5aMm-KvtvROpqfB8/getUpdates "HTTP/1.1 409 Conflict"
ERROR:telegram.ext.Application:No error handlers are registered, logging exception.
Traceback (most recent call last):
  File "/Users/rexrealingojr./Library/CloudStorage/GoogleDrive-rex15realingo@gmail.com/My Drive/Ai/.venv/lib/python3.13/site-packages/telegram/ext/_utils/networkloop.py", line 115, in network_retry_loop
    if not await do_action():
           ^^^^^^^^^^^^^^^^^
  File "/Users/rexrealingojr./Library/CloudStorage/GoogleDrive-rex15realingo@gmail.com/My Drive/Ai/.venv/lib/python3.13/site-packages/telegram/ext/_utils/networkloop.py", line 108, in do_action
    return action_cb_task.result()
           ~~~~~~~~~~~~~~~~~~~~~^^
  File "/Users/rexrealingojr./Library/CloudStorage/GoogleDrive-rex15realingo@gmail.com/My Drive/Ai/.venv/lib/python3.13/site-packages/telegram/ext/_updater.py", line 340, in polling_action_cb
    updates = await self.bot.get_updates(
              ^^^^^^^^^^^^^^^^^^^^^^^^^^^
    ...<3 lines>...
    )
    ^
  File "/Users/rexrealingojr./Library/CloudStorage/GoogleDrive-rex15realingo@gmail.com/My Drive/Ai/.venv/lib/python3.13/site-packages/telegram/ext/_extbot.py", line 669, in get_updates
    updates = await super().get_updates(
              ^^^^^^^^^^^^^^^^^^^^^^^^^^
    ...<9 lines>...
    )
    ^
  File "/Users/rexrealingojr./Library/CloudStorage/GoogleDrive-rex15realingo@gmail.com/My Drive/Ai/.venv/lib/python3.13/site-packages/telegram/_bot.py", line 4610, in get_updates
    await self._post(
    ^^^^^^^^^^^^^^^^^
    ...<7 lines>...
    ),
    ^
  File "/Users/rexrealingojr./Library/CloudStorage/GoogleDrive-rex15realingo@gmail.com/My Drive/Ai/.venv/lib/python3.13/site-packages/telegram/_bot.py", line 697, in _post
    return await self._do_post(
           ^^^^^^^^^^^^^^^^^^^^
    ...<6 lines>...
    )
    ^
  File "/Users/rexrealingojr./Library/CloudStorage/GoogleDrive-rex15realingo@gmail.com/My Drive/Ai/.venv/lib/python3.13/site-packages/telegram/ext/_extbot.py", line 369, in _do_post
    return await super()._do_post(
           ^^^^^^^^^^^^^^^^^^^^^^^
    ...<6 lines>...
    )
    ^
  File "/Users/rexrealingojr./Library/CloudStorage/GoogleDrive-rex15realingo@gmail.com/My Drive/Ai/.venv/lib/python3.13/site-packages/telegram/_bot.py", line 726, in _do_post
    result = await request.post(
             ^^^^^^^^^^^^^^^^^^^
    ...<6 lines>...
    )
    ^
  File "/Users/rexrealingojr./Library/CloudStorage/GoogleDrive-rex15realingo@gmail.com/My Drive/Ai/.venv/lib/python3.13/site-packages/telegram/request/_baserequest.py", line 197, in post
    result = await self._request_wrapper(
             ^^^^^^^^^^^^^^^^^^^^^^^^^^^^
    ...<7 lines>...
    )
    ^
  File "/Users/rexrealingojr./Library/CloudStorage/GoogleDrive-rex15realingo@gmail.com/My Drive/Ai/.venv/lib/python3.13/site-packages/telegram/request/_baserequest.py", line 374, in _request_wrapper
    raise exception
telegram.error.Conflict: Conflict: terminated by other getUpdates request; make sure that only one bot instance is running
INFO:httpx:HTTP Request: POST https://api.telegram.org/bot7779786808:AAHul6zZde15UvoPbGb5aMm-KvtvROpqfB8/getUpdates "HTTP/1.1 409 Conflict"
ERROR:telegram.ext.Application:No error handlers are registered, logging exception.
Traceback (most recent call last):
  File "/Users/rexrealingojr./Library/CloudStorage/GoogleDrive-rex15realingo@gmail.com/My Drive/Ai/.venv/lib/python3.13/site-packages/telegram/ext/_utils/networkloop.py", line 115, in network_retry_loop
    if not await do_action():
           ^^^^^^^^^^^^^^^^^
  File "/Users/rexrealingojr./Library/CloudStorage/GoogleDrive-rex15realingo@gmail.com/My Drive/Ai/.venv/lib/python3.13/site-packages/telegram/ext/_utils/networkloop.py", line 108, in do_action
    return action_cb_task.result()
           ~~~~~~~~~~~~~~~~~~~~~^^
  File "/Users/rexrealingojr./Library/CloudStorage/GoogleDrive-rex15realingo@gmail.com/My Drive/Ai/.venv/lib/python3.13/site-packages/telegram/ext/_updater.py", line 340, in polling_action_cb
    updates = await self.bot.get_updates(
              ^^^^^^^^^^^^^^^^^^^^^^^^^^^
    ...<3 lines>...
    )
    ^
  File "/Users/rexrealingojr./Library/CloudStorage/GoogleDrive-rex15realingo@gmail.com/My Drive/Ai/.venv/lib/python3.13/site-packages/telegram/ext/_extbot.py", line 669, in get_updates
    updates = await super().get_updates(
              ^^^^^^^^^^^^^^^^^^^^^^^^^^
    ...<9 lines>...
    )
    ^
  File "/Users/rexrealingojr./Library/CloudStorage/GoogleDrive-rex15realingo@gmail.com/My Drive/Ai/.venv/lib/python3.13/site-packages/telegram/_bot.py", line 4610, in get_updates
    await self._post(
    ^^^^^^^^^^^^^^^^^
    ...<7 lines>...
    ),
    ^
  File "/Users/rexrealingojr./Library/CloudStorage/GoogleDrive-rex15realingo@gmail.com/My Drive/Ai/.venv/lib/python3.13/site-packages/telegram/_bot.py", line 697, in _post
    return await self._do_post(
           ^^^^^^^^^^^^^^^^^^^^
    ...<6 lines>...
    )
    ^
  File "/Users/rexrealingojr./Library/CloudStorage/GoogleDrive-rex15realingo@gmail.com/My Drive/Ai/.venv/lib/python3.13/site-packages/telegram/ext/_extbot.py", line 369, in _do_post
    return await super()._do_post(
           ^^^^^^^^^^^^^^^^^^^^^^^
    ...<6 lines>...
    )
    ^
  File "/Users/rexrealingojr./Library/CloudStorage/GoogleDrive-rex15realingo@gmail.com/My Drive/Ai/.venv/lib/python3.13/site-packages/telegram/_bot.py", line 726, in _do_post
    result = await request.post(
             ^^^^^^^^^^^^^^^^^^^
    ...<6 lines>...
    )
    ^
  File "/Users/rexrealingojr./Library/CloudStorage/GoogleDrive-rex15realingo@gmail.com/My Drive/Ai/.venv/lib/python3.13/site-packages/telegram/request/_baserequest.py", line 197, in post
    result = await self._request_wrapper(
             ^^^^^^^^^^^^^^^^^^^^^^^^^^^^
    ...<7 lines>...
    )
    ^
  File "/Users/rexrealingojr./Library/CloudStorage/GoogleDrive-rex15realingo@gmail.com/My Drive/Ai/.venv/lib/python3.13/site-packages/telegram/request/_baserequest.py", line 374, in _request_wrapper
    raise exception
telegram.error.Conflict: Conflict: terminated by other getUpdates request; make sure that only one bot instance is running
INFO:httpx:HTTP Request: POST https://api.telegram.org/bot7779786808:AAHul6zZde15UvoPbGb5aMm-KvtvROpqfB8/getUpdates "HTTP/1.1 409 Conflict"
ERROR:telegram.ext.Application:No error handlers are registered, logging exception.
Traceback (most recent call last):
  File "/Users/rexrealingojr./Library/CloudStorage/GoogleDrive-rex15realingo@gmail.com/My Drive/Ai/.venv/lib/python3.13/site-packages/telegram/ext/_utils/networkloop.py", line 115, in network_retry_loop
    if not await do_action():
           ^^^^^^^^^^^^^^^^^
  File "/Users/rexrealingojr./Library/CloudStorage/GoogleDrive-rex15realingo@gmail.com/My Drive/Ai/.venv/lib/python3.13/site-packages/telegram/ext/_utils/networkloop.py", line 108, in do_action
    return action_cb_task.result()
           ~~~~~~~~~~~~~~~~~~~~~^^
  File "/Users/rexrealingojr./Library/CloudStorage/GoogleDrive-rex15realingo@gmail.com/My Drive/Ai/.venv/lib/python3.13/site-packages/telegram/ext/_updater.py", line 340, in polling_action_cb
    updates = await self.bot.get_updates(
              ^^^^^^^^^^^^^^^^^^^^^^^^^^^
    ...<3 lines>...
    )
    ^
  File "/Users/rexrealingojr./Library/CloudStorage/GoogleDrive-rex15realingo@gmail.com/My Drive/Ai/.venv/lib/python3.13/site-packages/telegram/ext/_extbot.py", line 669, in get_updates
    updates = await super().get_updates(
              ^^^^^^^^^^^^^^^^^^^^^^^^^^
    ...<9 lines>...
    )
    ^
  File "/Users/rexrealingojr./Library/CloudStorage/GoogleDrive-rex15realingo@gmail.com/My Drive/Ai/.venv/lib/python3.13/site-packages/telegram/_bot.py", line 4610, in get_updates
    await self._post(
    ^^^^^^^^^^^^^^^^^
    ...<7 lines>...
    ),
    ^
  File "/Users/rexrealingojr./Library/CloudStorage/GoogleDrive-rex15realingo@gmail.com/My Drive/Ai/.venv/lib/python3.13/site-packages/telegram/_bot.py", line 697, in _post
    return await self._do_post(
           ^^^^^^^^^^^^^^^^^^^^
    ...<6 lines>...
    )
    ^
  File "/Users/rexrealingojr./Library/CloudStorage/GoogleDrive-rex15realingo@gmail.com/My Drive/Ai/.venv/lib/python3.13/site-packages/telegram/ext/_extbot.py", line 369, in _do_post
    return await super()._do_post(
           ^^^^^^^^^^^^^^^^^^^^^^^
    ...<6 lines>...
    )
    ^
  File "/Users/rexrealingojr./Library/CloudStorage/GoogleDrive-rex15realingo@gmail.com/My Drive/Ai/.venv/lib/python3.13/site-packages/telegram/_bot.py", line 726, in _do_post
    result = await request.post(
             ^^^^^^^^^^^^^^^^^^^
    ...<6 lines>...
    )
    ^
  File "/Users/rexrealingojr./Library/CloudStorage/GoogleDrive-rex15realingo@gmail.com/My Drive/Ai/.venv/lib/python3.13/site-packages/telegram/request/_baserequest.py", line 197, in post
    result = await self._request_wrapper(
             ^^^^^^^^^^^^^^^^^^^^^^^^^^^^
    ...<7 lines>...
    )
    ^
  File "/Users/rexrealingojr./Library/CloudStorage/GoogleDrive-rex15realingo@gmail.com/My Drive/Ai/.venv/lib/python3.13/site-packages/telegram/request/_baserequest.py", line 374, in _request_wrapper
    raise exception
telegram.error.Conflict: Conflict: terminated by other getUpdates request; make sure that only one bot instance is running
INFO:httpx:HTTP Request: POST https://api.telegram.org/bot7779786808:AAHul6zZde15UvoPbGb5aMm-KvtvROpqfB8/getUpdates "HTTP/1.1 409 Conflict"
ERROR:telegram.ext.Application:No error handlers are registered, logging exception.
Traceback (most recent call last):
  File "/Users/rexrealingojr./Library/CloudStorage/GoogleDrive-rex15realingo@gmail.com/My Drive/Ai/.venv/lib/python3.13/site-packages/telegram/ext/_utils/networkloop.py", line 115, in network_retry_loop
    if not await do_action():
           ^^^^^^^^^^^^^^^^^
  File "/Users/rexrealingojr./Library/CloudStorage/GoogleDrive-rex15realingo@gmail.com/My Drive/Ai/.venv/lib/python3.13/site-packages/telegram/ext/_utils/networkloop.py", line 108, in do_action
    return action_cb_task.result()
           ~~~~~~~~~~~~~~~~~~~~~^^
  File "/Users/rexrealingojr./Library/CloudStorage/GoogleDrive-rex15realingo@gmail.com/My Drive/Ai/.venv/lib/python3.13/site-packages/telegram/ext/_updater.py", line 340, in polling_action_cb
    updates = await self.bot.get_updates(
              ^^^^^^^^^^^^^^^^^^^^^^^^^^^
    ...<3 lines>...
    )
    ^
  File "/Users/rexrealingojr./Library/CloudStorage/GoogleDrive-rex15realingo@gmail.com/My Drive/Ai/.venv/lib/python3.13/site-packages/telegram/ext/_extbot.py", line 669, in get_updates
    updates = await super().get_updates(
              ^^^^^^^^^^^^^^^^^^^^^^^^^^
    ...<9 lines>...
    )
    ^
  File "/Users/rexrealingojr./Library/CloudStorage/GoogleDrive-rex15realingo@gmail.com/My Drive/Ai/.venv/lib/python3.13/site-packages/telegram/_bot.py", line 4610, in get_updates
    await self._post(
    ^^^^^^^^^^^^^^^^^
    ...<7 lines>...
    ),
    ^
  File "/Users/rexrealingojr./Library/CloudStorage/GoogleDrive-rex15realingo@gmail.com/My Drive/Ai/.venv/lib/python3.13/site-packages/telegram/_bot.py", line 697, in _post
    return await self._do_post(
           ^^^^^^^^^^^^^^^^^^^^
    ...<6 lines>...
    )
    ^
  File "/Users/rexrealingojr./Library/CloudStorage/GoogleDrive-rex15realingo@gmail.com/My Drive/Ai/.venv/lib/python3.13/site-packages/telegram/ext/_extbot.py", line 369, in _do_post
    return await super()._do_post(
           ^^^^^^^^^^^^^^^^^^^^^^^
    ...<6 lines>...
    )
    ^
  File "/Users/rexrealingojr./Library/CloudStorage/GoogleDrive-rex15realingo@gmail.com/My Drive/Ai/.venv/lib/python3.13/site-packages/telegram/_bot.py", line 726, in _do_post
    result = await request.post(
             ^^^^^^^^^^^^^^^^^^^
    ...<6 lines>...
    )
    ^
  File "/Users/rexrealingojr./Library/CloudStorage/GoogleDrive-rex15realingo@gmail.com/My Drive/Ai/.venv/lib/python3.13/site-packages/telegram/request/_baserequest.py", line 197, in post
    result = await self._request_wrapper(
             ^^^^^^^^^^^^^^^^^^^^^^^^^^^^
    ...<7 lines>...
    )
    ^
  File "/Users/rexrealingojr./Library/CloudStorage/GoogleDrive-rex15realingo@gmail.com/My Drive/Ai/.venv/lib/python3.13/site-packages/telegram/request/_baserequest.py", line 374, in _request_wrapper
    raise exception
telegram.error.Conflict: Conflict: terminated by other getUpdates request; make sure that only one bot instance is running
INFO:httpx:HTTP Request: POST https://api.telegram.org/bot7779786808:AAHul6zZde15UvoPbGb5aMm-KvtvROpqfB8/getUpdates "HTTP/1.1 409 Conflict"
ERROR:telegram.ext.Application:No error handlers are registered, logging exception.
Traceback (most recent call last):
  File "/Users/rexrealingojr./Library/CloudStorage/GoogleDrive-rex15realingo@gmail.com/My Drive/Ai/.venv/lib/python3.13/site-packages/telegram/ext/_utils/networkloop.py", line 115, in network_retry_loop
    if not await do_action():
           ^^^^^^^^^^^^^^^^^
  File "/Users/rexrealingojr./Library/CloudStorage/GoogleDrive-rex15realingo@gmail.com/My Drive/Ai/.venv/lib/python3.13/site-packages/telegram/ext/_utils/networkloop.py", line 108, in do_action
    return action_cb_task.result()
           ~~~~~~~~~~~~~~~~~~~~~^^
  File "/Users/rexrealingojr./Library/CloudStorage/GoogleDrive-rex15realingo@gmail.com/My Drive/Ai/.venv/lib/python3.13/site-packages/telegram/ext/_updater.py", line 340, in polling_action_cb
    updates = await self.bot.get_updates(
              ^^^^^^^^^^^^^^^^^^^^^^^^^^^
    ...<3 lines>...
    )
    ^
  File "/Users/rexrealingojr./Library/CloudStorage/GoogleDrive-rex15realingo@gmail.com/My Drive/Ai/.venv/lib/python3.13/site-packages/telegram/ext/_extbot.py", line 669, in get_updates
    updates = await super().get_updates(
              ^^^^^^^^^^^^^^^^^^^^^^^^^^
    ...<9 lines>...
    )
    ^
  File "/Users/rexrealingojr./Library/CloudStorage/GoogleDrive-rex15realingo@gmail.com/My Drive/Ai/.venv/lib/python3.13/site-packages/telegram/_bot.py", line 4610, in get_updates
    await self._post(
    ^^^^^^^^^^^^^^^^^
    ...<7 lines>...
    ),
    ^
  File "/Users/rexrealingojr./Library/CloudStorage/GoogleDrive-rex15realingo@gmail.com/My Drive/Ai/.venv/lib/python3.13/site-packages/telegram/_bot.py", line 697, in _post
    return await self._do_post(
           ^^^^^^^^^^^^^^^^^^^^
    ...<6 lines>...
    )
    ^
  File "/Users/rexrealingojr./Library/CloudStorage/GoogleDrive-rex15realingo@gmail.com/My Drive/Ai/.venv/lib/python3.13/site-packages/telegram/ext/_extbot.py", line 369, in _do_post
    return await super()._do_post(
           ^^^^^^^^^^^^^^^^^^^^^^^
    ...<6 lines>...
    )
    ^
  File "/Users/rexrealingojr./Library/CloudStorage/GoogleDrive-rex15realingo@gmail.com/My Drive/Ai/.venv/lib/python3.13/site-packages/telegram/_bot.py", line 726, in _do_post
    result = await request.post(
             ^^^^^^^^^^^^^^^^^^^
    ...<6 lines>...
    )
    ^
  File "/Users/rexrealingojr./Library/CloudStorage/GoogleDrive-rex15realingo@gmail.com/My Drive/Ai/.venINFO:httpx:HTTP Request: POST https://api.telegram.org/bot7779786808:AAHul6zZde15UvoPbGb5aMm-KvtvROpqfB8/getUpdates "HTTP/1.1 200 OK"
INFO:httpx:HTTP Request: POST https://api.telegram.org/bot7779786808:AAHul6zZde15UvoPbGb5aMm-KvtvROpqfB8/getUpdates "HTTP/1.1 200 OK"
INFO:httpx:HTTP Request: POST https://api.telegram.org/bot7779786808:AAHul6zZde15UvoPbGb5aMm-KvtvROpqfB8/getUpdates "HTTP/1.1 200 OK"
INFO:httpx:HTTP Request: POST https://api.telegram.org/bot7779786808:AAHul6zZde15UvoPbGb5aMm-KvtvROpqfB8/getUpdates "HTTP/1.1 200 OK"
INFO:httpx:HTTP Request: POST https://api.telegram.org/bot7779786808:AAHul6zZde15UvoPbGb5aMm-KvtvROpqfB8/getUpdates "HTTP/1.1 200 OK"
INFO:httpx:HTTP Request: POST https://api.telegram.org/bot7779786808:AAHul6zZde15UvoPbGb5aMm-KvtvROpqfB8/getUpdates "HTTP/1.1 200 OK"
INFO:httpx:HTTP Request: POST https://api.telegram.org/bot7779786808:AAHul6zZde15UvoPbGb5aMm-KvtvROpqfB8/getUpdates "HTTP/1.1 200 OK"
INFO:httpx:HTTP Request: POST https://api.telegram.org/bot7779786808:AAHul6zZde15UvoPbGb5aMm-KvtvROpqfB8/getUpdates "HTTP/1.1 200 OK"
INFO:httpx:HTTP Request: POST https://api.telegram.org/bot7779786808:AAHul6zZde15UvoPbGb5aMm-KvtvROpqfB8/getUpdates "HTTP/1.1 200 OK"
INFO:httpx:HTTP Request: POST https://api.telegram.org/bot7779786808:AAHul6zZde15UvoPbGb5aMm-KvtvROpqfB8/getUpdates "HTTP/1.1 200 OK"
INFO:httpx:HTTP Request: POST https://api.telegram.org/bot7779786808:AAHul6zZde15UvoPbGb5aMm-KvtvROpqfB8/getUpdates "HTTP/1.1 200 OK"
INFO:httpx:HTTP Request: POST https://api.telegram.org/bot7779786808:AAHul6zZde15UvoPbGb5aMm-KvtvROpqfB8/getUpdates "HTTP/1.1 200 OK"
INFO:httpx:HTTP Request: POST https://api.telegram.org/bot7779786808:AAHul6zZde15UvoPbGb5aMm-KvtvROpqfB8/getUpdates "HTTP/1.1 200 OK"
INFO:httpx:HTTP Request: POST https://api.telegram.org/bot7779786808:AAHul6zZde15UvoPbGb5aMm-KvtvROpqfB8/getUpdates "HTTP/1.1 200 OK"
INFO:httpx:HTTP Request: POST https://api.telegram.org/bot7779786808:AAHul6zZde15UvoPbGb5aMm-KvtvROpqfB8/getUpdates "HTTP/1.1 200 OK"
INFO:httpx:HTTP Request: POST https://api.telegram.org/bot7779786808:AAHul6zZde15UvoPbGb5aMm-KvtvROpqfB8/getUpdates "HTTP/1.1 200 OK"
INFO:httpx:HTTP Request: POST https://api.telegram.org/bot7779786808:AAHul6zZde15UvoPbGb5aMm-KvtvROpqfB8/sendMessage "HTTP/1.1 200 OK"
INFO:httpx:HTTP Request: POST https://api.telegram.org/bot7779786808:AAHul6zZde15UvoPbGb5aMm-KvtvROpqfB8/getUpdates "HTTP/1.1 200 OK"
INFO:httpx:HTTP Request: POST https://api.telegram.org/bot7779786808:AAHul6zZde15UvoPbGb5aMm-KvtvROpqfB8/sendMessage "HTTP/1.1 200 OK"
INFO:httpx:HTTP Request: POST https://api.telegram.org/bot7779786808:AAHul6zZde15UvoPbGb5aMm-KvtvROpqfB8/getUpdates "HTTP/1.1 409 Conflict"
ERROR:telegram.ext.Application:No error handlers are registered, logging exception.
Traceback (most recent call last):
  File "/Users/rexrealingojr./Library/CloudStorage/GoogleDrive-rex15realingo@gmail.com/My Drive/Ai/.venv/lib/python3.13/site-packages/telegram/ext/_utils/networkloop.py", line 115, in network_retry_loop
    if not await do_action():
           ^^^^^^^^^^^^^^^^^
  File "/Users/rexrealingojr./Library/CloudStorage/GoogleDrive-rex15realingo@gmail.com/My Drive/Ai/.venv/lib/python3.13/site-packages/telegram/ext/_utils/networkloop.py", line 108, in do_action
    return action_cb_task.result()
           ~~~~~~~~~~~~~~~~~~~~~^^
  File "/Users/rexrealingojr./Library/CloudStorage/GoogleDrive-rex15realingo@gmail.com/My Drive/Ai/.venv/lib/python3.13/site-packages/telegram/ext/_updater.py", line 340, in polling_action_cb
    updates = await self.bot.get_updates(
              ^^^^^^^^^^^^^^^^^^^^^^^^^^^
    ...<3 lines>...
    )
    ^
  File "/Users/rexrealingojr./Library/CloudStorage/GoogleDrive-rex15realingo@gmail.com/My Drive/Ai/.venv/lib/python3.13/site-packages/telegram/ext/_extbot.py", line 669, in get_updates
    updates = await super().get_updates(
              ^^^^^^^^^^^^^^^^^^^^^^^^^^
    ...<9 lines>...
    )
    ^
  File "/Users/rexrealingojr./Library/CloudStorage/GoogleDrive-rex15realingo@gmail.com/My Drive/Ai/.venv/lib/python3.13/site-packages/telegram/_bot.py", line 4610, in get_updates
    await self._post(
    ^^^^^^^^^^^^^^^^^
    ...<7 lines>...
    ),
    ^
  File "/Users/rexrealingojr./Library/CloudStorage/GoogleDrive-rex15realingo@gmail.com/My Drive/Ai/.venv/lib/python3.13/site-packages/telegram/_bot.py", line 697, in _post
    return await self._do_post(
           ^^^^^^^^^^^^^^^^^^^^
    ...<6 lines>...
    )
    ^
  File "/Users/rexrealingojr./Library/CloudStorage/GoogleDrive-rex15realingo@gmail.com/My Drive/Ai/.venv/lib/python3.13/site-packages/telegram/ext/_extbot.py", line 369, in _do_post
    return await super()._do_post(
           ^^^^^^^^^^^^^^^^^^^^^^^
    ...<6 lines>...
    )
    ^
  File "/Users/rexrealingojr./Library/CloudStorage/GoogleDrive-rex15realingo@gmail.com/My Drive/Ai/.venv/lib/python3.13/site-packages/telegram/_bot.py", line 726, in _do_post
    result = await request.post(
             ^^^^^^^^^^^^^^^^^^^
    ...<6 lines>...
    )
    ^
  File "/Users/rexrealingojr./Library/CloudStorage/GoogleDrive-rex15realingo@gmail.com/My Drive/Ai/.venv/lib/python3.13/site-packages/telegram/request/_baserequest.py", line 197, in post
    result = await self._request_wrapper(
             ^^^^^^^^^^^^^^^^^^^^^^^^^^^^
    ...<7 lines>...
    )
    ^
  File "/Users/rexrealingojr./Library/CloudStorage/GoogleDrive-rex15realingo@gmail.com/My Drive/Ai/.venv/lib/python3.13/site-packages/telegram/request/_baserequest.py", line 374, in _request_wrapper
    raise exception
telegram.error.Conflict: Conflict: terminated by other getUpdates request; make sure that only one bot instance is running
INFO:httpx:HTTP Request: POST https://api.telegram.org/bot7779786808:AAHul6zZde15UvoPbGb5aMm-KvtvROpqfB8/getUpdates "HTTP/1.1 200 OK"
INFO:httpx:HTTP Request: POST https://api.telegram.org/bot7779786808:AAHul6zZde15UvoPbGb5aMm-KvtvROpqfB8/getUpdates "HTTP/1.1 200 OK"
INFO:httpx:HTTP Request: POST https://api.telegram.org/bot7779786808:AAHul6zZde15UvoPbGb5aMm-KvtvROpqfB8/getUpdates "HTTP/1.1 200 OK"
INFO:httpx:HTTP Request: POST https://api.telegram.org/bot7779786808:AAHul6zZde15UvoPbGb5aMm-KvtvROpqfB8/getUpdates "HTTP/1.1 200 OK"
INFO:httpx:HTTP Request: POST https://api.telegram.org/bot7779786808:AAHul6zZde15UvoPbGb5aMm-KvtvROpqfB8/getUpdates "HTTP/1.1 200 OK"
INFO:httpx:HTTP Request: POST https://api.telegram.org/bot7779786808:AAHul6zZde15UvoPbGb5aMm-KvtvROpqfB8/getUpdates "HTTP/1.1 200 OK"
INFO:httpx:HTTP Request: POST https://api.telegram.org/bot7779786808:AAHul6zZde15UvoPbGb5aMm-KvtvROpqfB8/getUpdates "HTTP/1.1 200 OK"
INFO:httpx:HTTP Request: POST https://api.telegram.org/bot7779786808:AAHul6zZde15UvoPbGb5aMm-KvtvROpqfB8/getUpdates "HTTP/1.1 200 OK"
INFO:httpx:HTTP Request: POST https://api.telegram.org/bot7779786808:AAHul6zZde15UvoPbGb5aMm-KvtvROpqfB8/getUpdates "HTTP/1.1 200 OK"
INFO:httpx:HTTP Request: POST https://api.telegram.org/bot7779786808:AAHul6zZde15UvoPbGb5aMm-KvtvROpqfB8/getUpdates "HTTP/1.1 200 OK"
INFO:httpx:HTTP Request: POST https://api.telegram.org/bot7779786808:AAHul6zZde15UvoPbGb5aMm-KvtvROpqfB8/getUpdates "HTTP/1.1 200 OK"
INFO:httpx:HTTP Request: POST https://api.telegram.org/bot7779786808:AAHul6zZde15UvoPbGb5aMm-KvtvROpqfB8/sendMessage "HTTP/1.1 200 OK"
INFO:httpx:HTTP Request: POST https://api.telegram.org/bot7779786808:AAHul6zZde15UvoPbGb5aMm-KvtvROpqfB8/sendMessage "HTTP/1.1 200 OK"
INFO:httpx:HTTP Request: POST https://api.telegram.org/bot7779786808:AAHul6zZde15UvoPbGb5aMm-KvtvROpqfB8/getUpdates "HTTP/1.1 200 OK"
INFO:httpx:HTTP Request: POST https://api.telegram.org/bot7779786808:AAHul6zZde15UvoPbGb5aMm-KvtvROpqfB8/sendMessage "HTTP/1.1 200 OK"
INFO:httpx:HTTP Request: POST https://api.telegram.org/bot7779786808:AAHul6zZde15UvoPbGb5aMm-KvtvROpqfB8/getUpdates "HTTP/1.1 200 OK"
INFO:httpx:HTTP Request: POST https://api.telegram.org/bot7779786808:AAHul6zZde15UvoPbGb5aMm-KvtvROpqfB8/sendMessage "HTTP/1.1 200 OK"
INFO:httpx:HTTP Request: POST https://api.telegram.org/bot7779786808:AAHul6zZde15UvoPbGb5aMm-KvtvROpqfB8/getUpdates "HTTP/1.1 200 OK"
INFO:httpx:HTTP Request: POST https://api.telegram.org/bot7779786808:AAHul6zZde15UvoPbGb5aMm-KvtvROpqfB8/sendMessage "HTTP/1.1 200 OK"
INFO:httpx:HTTP Request: POST https://api.telegram.org/bot7779786808:AAHul6zZde15UvoPbGb5aMm-KvtvROpqfB8/sendMessage "HTTP/1.1 200 OK"
INFO:httpx:HTTP Request: POST https://api.telegram.org/bot7779786808:AAHul6zZde15UvoPbGb5aMm-KvtvROpqfB8/getUpdates "HTTP/1.1 409 Conflict"
ERROR:telegram.ext.Application:No error handlers are registered, logging exception.
Traceback (most recent call last):
  File "/Users/rexrealingojr./Library/CloudStorage/GoogleDrive-rex15realingo@gmail.com/My Drive/Ai/.venv/lib/python3.13/site-packages/telegram/ext/_utils/networkloop.py", line 115, in network_retry_loop
    if not await do_action():
           ^^^^^^^^^^^^^^^^^
  File "/Users/rexrealingojr./Library/CloudStorage/GoogleDrive-rex15realingo@gmail.com/My Drive/Ai/.venv/lib/python3.13/site-packages/telegram/ext/_utils/networkloop.py", line 108, in do_action
    return action_cb_task.result()
           ~~~~~~~~~~~~~~~~~~~~~^^
  File "/Users/rexrealingojr./Library/CloudStorage/GoogleDrive-rex15realingo@gmail.com/My Drive/Ai/.venv/lib/python3.13/site-packages/telegram/ext/_updater.py", line 340, in polling_action_cb
    updates = await self.bot.get_updates(
              ^^^^^^^^^^^^^^^^^^^^^^^^^^^
    ...<3 lines>...
    )
    ^
  File "/Users/rexrealingojr./Library/CloudStorage/GoogleDrive-rex15realingo@gmail.com/My Drive/Ai/.venv/lib/python3.13/site-packages/telegram/ext/_extbot.py", line 669, in get_updates
    updates = await super().get_updates(
              ^^^^^^^^^^^^^^^^^^^^^^^^^^
    ...<9 lines>...
    )
    ^
  File "/Users/rexrealingojr./Library/CloudStorage/GoogleDrive-rex15realingo@gmail.com/My Drive/Ai/.venv/lib/python3.13/site-packages/telegram/_bot.py", line 4610, in get_updates
    await self._post(
    ^^^^^^^^^^^^^^^^^
    ...<7 lines>...
    ),
    ^
  File "/Users/rexrealingojr./Library/CloudStorage/GoogleDrive-rex15realingo@gmail.com/My Drive/Ai/.venv/lib/python3.13/site-packages/telegram/_bot.py", line 697, in _post
    return await self._do_post(
           ^^^^^^^^^^^^^^^^^^^^
    ...<6 lines>...
    )
    ^
  File "/Users/rexrealingojr./Library/CloudStorage/GoogleDrive-rex15realingo@gmail.com/My Drive/Ai/.venv/lib/python3.13/site-packages/telegram/ext/_extbot.py", line 369, in _do_post
    return await super()._do_post(
           ^^^^^^^^^^^^^^^^^^^^^^^
    ...<6 lines>...
    )
    ^
  File "/Users/rexrealingojr./Library/CloudStorage/GoogleDrive-rex15realingo@gmail.com/My Drive/Ai/.venv/lib/python3.13/site-packages/telegram/_bot.py", line 726, in _do_post
    result = await request.post(
             ^^^^^^^^^^^^^^^^^^^
    ...<6 lines>...
    )
    ^
  File "/Users/rexrealingojr./Library/CloudStorage/GoogleDrive-rex15realingo@gmail.com/My Drive/Ai/.venv/lib/python3.13/site-packages/telegram/request/_baserequest.py", line 197, in post
    result = await self._request_wrapper(
             ^^^^^^^^^^^^^^^^^^^^^^^^^^^^
    ...<7 lines>...
    )
    ^
  File "/Users/rexrealingojr./Library/CloudStorage/GoogleDrive-rex15realingo@gmail.com/My Drive/Ai/.venv/lib/python3.13/site-packages/telegram/request/_baserequest.py", line 374, in _request_wrapper
    raise exception
telegram.error.Conflict: Conflict: terminated by other getUpdates request; make sure that only one bot instance is running
INFO:httpx:HTTP Request: POST https://api.telegram.org/bot7779786808:AAHul6zZde15UvoPbGb5aMm-KvtvROpqfB8/getUpdates "HTTP/1.1 409 Conflict"
ERROR:telegram.ext.Application:No error handlers are registered, logging exception.
Traceback (most recent call last):
  File "/Users/rexrealingojr./Library/CloudStorage/GoogleDrive-rex15realingo@gmail.com/My Drive/Ai/.venv/lib/python3.13/site-packages/telegram/ext/_utils/networkloop.py", line 115, in network_retry_loop
    if not await do_action():
           ^^^^^^^^^^^^^^^^^
  File "/Users/rexrealingojr./Library/CloudStorage/GoogleDrive-rex15realingo@gmail.com/My Drive/Ai/.venv/lib/python3.13/site-packages/telegram/ext/_utils/networkloop.py", line 108, in do_action
    return action_cb_task.result()
           ~~~~~~~~~~~~~~~~~~~~~^^
  File "/Users/rexrealingojr./Library/CloudStorage/GoogleDrive-rex15realingo@gmail.com/My Drive/Ai/.venv/lib/python3.13/site-packages/telegram/ext/_updater.py", line 340, in polling_action_cb
    updates = await self.bot.get_updates(
              ^^^^^^^^^^^^^^^^^^^^^^^^^^^
    ...<3 lines>...
    )
    ^
  File "/Users/rexrealingojr./Library/CloudStorage/GoogleDrive-rex15realingo@gmail.com/My Drive/Ai/.venv/lib/python3.13/site-packages/telegram/ext/_extbot.py", line 669, in get_updates
    updates = await super().get_updates(
              ^^^^^^^^^^^^^^^^^^^^^^^^^^
    ...<9 lines>...
    )
    ^
  File "/Users/rexrealingojr./Library/CloudStorage/GoogleDrive-rex15realingo@gmail.com/My Drive/Ai/.venv/lib/python3.13/site-packages/telegram/_bot.py", line 4610, in get_updates
    await self._post(
    ^^^^^^^^^^^^^^^^^
    ...<7 lines>...
    ),
    ^
  File "/Users/rexrealingojr./Library/CloudStorage/GoogleDrive-rex15realingo@gmail.com/My Drive/Ai/.venv/lib/python3.13/site-packages/telegram/_bot.py", line 697, in _post
    return await self._do_post(
           ^^^^^^^^^^^^^^^^^^^^
    ...<6 lines>...
    )
    ^
  File "/Users/rexrealingojr./Library/CloudStorage/GoogleDrive-rex15realingo@gmail.com/My Drive/Ai/.venv/lib/python3.13/site-packages/telegram/ext/_extbot.py", line 369, in _do_post
    return await super()._do_post(
           ^^^^^^^^^^^^^^^^^^^^^^^
    ...<6 lines>...
    )
    ^
  File "/Users/rexrealingojr./Library/CloudStorage/GoogleDrive-rex15realingo@gmail.com/My Drive/Ai/.venv/lib/python3.13/site-packages/telegram/_bot.py", line 726, in _do_post
    result = await request.post(
             ^^^^^^^^^^^^^^^^^^^
    ...<6 lines>...
    )
    ^
  File "/Users/rexrealingojr./Library/CloudStorage/GoogleDrive-rex15realingo@gmail.com/My Drive/Ai/.venv/lib/python3.13/site-packages/telegram/request/_baserequest.py", line 197, in post
    result = await self._request_wrapper(
             ^^^^^^^^^^^^^^^^^^^^^^^^^^^^
    ...<7 lines>...
    )
    ^
  File "/Users/rexrealingojr./Library/CloudStorage/GoogleDrive-rex15realingo@gmail.com/My Drive/Ai/.venv/lib/python3.13/site-packages/telegram/request/_baserequest.py", line 374, in _request_wrapper
    raise exception
telegram.error.Conflict: Conflict: terminated by other getUpdates request; make sure that only one bot instance is running
INFO:httpx:HTTP Request: POST https://api.telegram.org/bot7779786808:AAHul6zZde15UvoPbGb5aMm-KvtvROpqfB8/getUpdates "HTTP/1.1 409 Conflict"
ERROR:telegram.ext.Application:No error handlers are registered, logging exception.
Traceback (most recent call last):
  File "/Users/rexrealingojr./Library/CloudStorage/GoogleDrive-rex15realingo@gmail.com/My Drive/Ai/.venv/lib/python3.13/site-packages/telegram/ext/_utils/networkloop.py", line 115, in network_retry_loop
    if not await do_action():
           ^^^^^^^^^^^^^^^^^
  File "/Users/rexrealingojr./Library/CloudStorage/GoogleDrive-rex15realingo@gmail.com/My Drive/Ai/.venv/lib/python3.13/site-packages/telegram/ext/_utils/networkloop.py", line 108, in do_action
    return action_cb_task.result()
           ~~~~~~~~~~~~~~~~~~~~~^^
  File "/Users/rexrealingojr./Library/CloudStorage/GoogleDrive-rex15realingo@gmail.com/My Drive/Ai/.venv/lib/python3.13/site-packages/telegram/ext/_updater.py", line 340, in polling_action_cb
    updates = await self.bot.get_updates(
              ^^^^^^^^^^^^^^^^^^^^^^^^^^^
    ...<3 lines>...
    )
    ^
  File "/Users/rexrealingojr./Library/CloudStorage/GoogleDrive-rex15realingo@gmail.com/My Drive/Ai/.venv/lib/python3.13/site-packages/telegram/ext/_extbot.py", line 669, in get_updates
    updates = await super().get_updates(
              ^^^^^^^^^^^^^^^^^^^^^^^^^^
    ...<9 lines>...
    )
    ^
  File "/Users/rexrealingojr./Library/CloudStorage/GoogleDrive-rex15realingo@gmail.com/My Drive/Ai/.venv/lib/python3.13/site-packages/telegram/_bot.py", line 4610, in get_updates
    await self._post(
    ^^^^^^^^^^^^^^^^^
    ...<7 lines>...
    ),
    ^
  File "/Users/rexrealingojr./Library/CloudStorage/GoogleDrive-rex15realingo@gmail.com/My Drive/Ai/.venv/lib/python3.13/site-packages/telegram/_bot.py", line 697, in _post
    return await self._do_post(
           ^^^^^^^^^^^^^^^^^^^^
    ...<6 lines>...
    )
    ^
  File "/Users/rexrealingojr./Library/CloudStorage/GoogleDrive-rex15realingo@gmail.com/My Drive/Ai/.venv/lib/python3.13/site-packages/telegram/ext/_extbot.py", line 369, in _do_post
    return await super()._do_post(
           ^^^^^^^^^^^^^^^^^^^^^^^
    ...<6 lines>...
    )
    ^
  File "/Users/rexrealingojr./Library/CloudStorage/GoogleDrive-rex15realingo@gmail.com/My Drive/Ai/.venv/lib/python3.13/site-packages/telegram/_bot.py", line 726, in _do_post
    result = await request.post(
             ^^^^^^^^^^^^^^^^^^^
    ...<6 lines>...
    )
    ^
  File "/Users/rexrealingojr./Library/CloudStorage/GoogleDrive-rex15realingo@gmail.com/My Drive/Ai/.venv/lib/python3.13/site-packages/telegram/request/_baserequest.py", line 197, in post
    result = await self._request_wrapper(
             ^^^^^^^^^^^^^^^^^^^^^^^^^^^^
    ...<7 lines>...
    )
    ^
  File "/Users/rexrealingojr./Library/CloudStorage/GoogleDrive-rex15realingo@gmail.com/My Drive/Ai/.venv/lib/python3.13/site-packages/telegram/request/_baserequest.py", line 374, in _request_wrapper
    raise exception
telegram.error.Conflict: Conflict: terminated by other getUpdates request; make sure that only one bot instance is running
INFO:httpx:HTTP Request: POST https://api.telegram.org/bot7779786808:AAHul6zZde15UvoPbGb5aMm-KvtvROpqfB8/getUpdates "HTTP/1.1 409 Conflict"
ERROR:telegram.ext.Application:No error handlers are registered, logging exception.
Traceback (most recent call last):
  File "/Users/rexrealingojr./Library/CloudStorage/GoogleDrive-rex15realingo@gmail.com/My Drive/Ai/.venv/lib/python3.13/site-packages/telegram/ext/_utils/networkloop.py", line 115, in network_retry_loop
    if not await do_action():
           ^^^^^^^^^^^^^^^^^
  File "/Users/rexrealingojr./Library/CloudStorage/GoogleDrive-rex15realingo@gmail.com/My Drive/Ai/.venv/lib/python3.13/site-packages/telegram/ext/_utils/networkloop.py", line 108, in do_action
    return action_cb_task.result()
           ~~~~~~~~~~~~~~~~~~~~~^^
  File "/Users/rexrealingojr./Library/CloudStorage/GoogleDrive-rex15realingo@gmail.com/My Drive/Ai/.venv/lib/python3.13/site-packages/telegram/ext/_updater.py", line 340, in polling_action_cb
    updates = await self.bot.get_updates(
              ^^^^^^^^^^^^^^^^^^^^^^^^^^^
    ...<3 lines>...
    )
    ^
  File "/Users/rexrealingojr./Library/CloudStorage/GoogleDrive-rex15realingo@gmail.com/My Drive/Ai/.venv/lib/python3.13/site-packages/telegram/ext/_extbot.py", line 669, in get_updates
    updates = await super().get_updates(
              ^^^^^^^^^^^^^^^^^^^^^^^^^^
    ...<9 lines>...
    )
    ^
  File "/Users/rexrealingojr./Library/CloudStorage/GoogleDrive-rex15realingo@gmail.com/My Drive/Ai/.venv/lib/python3.13/site-packages/telegram/_bot.py", line 4610, in get_updates
    await self._post(
    ^^^^^^^^^^^^^^^^^
    ...<7 lines>...
    ),
    ^
  File "/Users/rexrealingojr./Library/CloudStorage/GoogleDrive-rex15realingo@gmail.com/My Drive/Ai/.venv/lib/python3.13/site-packages/telegram/_bot.py", line 697, in _post
    return await self._do_post(
           ^^^^^^^^^^^^^^^^^^^^
    ...<6 lines>...
    )
    ^
  File "/Users/rexrealingojr./Library/CloudStorage/GoogleDrive-rex15realingo@gmail.com/My Drive/Ai/.venv/lib/python3.13/site-packages/telegram/ext/_extbot.py", line 369, in _do_post
    return await super()._do_post(
           ^^^^^^^^^^^^^^^^^^^^^^^
    ...<6 lines>...
    )
    ^
  File "/Users/rexrealingojr./Library/CloudStorage/GoogleDrive-rex15realingo@gmail.com/My Drive/Ai/.venv/lib/python3.13/site-packages/telegram/_bot.py", line 726, in _do_post
    result = await request.post(
             ^^^^^^^^^^^^^^^^^^^
    ...<6 lines>...
    )
    ^
  File "/Users/rexrealingojr./Library/CloudStorage/GoogleDrive-rex15realingo@gmail.com/My Drive/Ai/.venv/lib/python3.13/site-packages/telegram/request/_baserequest.py", line 197, in post
    result = await self._request_wrapper(
             ^^^^^^^^^^^^^^^^^^^^^^^^^^^^
    ...<7 lines>...
    )
    ^
  File "/Users/rexrealingojr./Library/CloudStorage/GoogleDrive-rex15realingo@gmail.com/My Drive/Ai/.venv/lib/python3.13/site-packages/telegram/request/_baserequest.py", line 374, in _request_wrapper
    raise exception
telegram.error.Conflict: Conflict: terminated by other getUpdates request; make sure that only one bot instance is running
INFO:httpx:HTTP Request: POST https://api.telegram.org/bot7779786808:AAHul6zZde15UvoPbGb5aMm-KvtvROpqfB8/getUpdates "HTTP/1.1 200 OK"
INFO:httpx:HTTP Request: POST https://api.telegram.org/bot7779786808:AAHul6zZde15UvoPbGb5aMm-KvtvROpqfB8/sendMessage "HTTP/1.1 200 OK"
INFO:httpx:HTTP Request: POST https://api.telegram.org/bot7779786808:AAHul6zZde15UvoPbGb5aMm-KvtvROpqfB8/sendMessage "HTTP/1.1 200 OK"
INFO:httpx:HTTP Request: POST https://api.telegram.org/bot7779786808:AAHul6zZde15UvoPbGb5aMm-KvtvROpqfB8/getUpdates "HTTP/1.1 409 Conflict"
ERROR:telegram.ext.Application:No error handlers are registered, logging exception.
Traceback (most recent call last):
  File "/Users/rexrealingojr./Library/CloudStorage/GoogleDrive-rex15realingo@gmail.com/My Drive/Ai/.venv/lib/python3.13/site-packages/telegram/ext/_utils/networkloop.py", line 115, in network_retry_loop
    if not await do_action():
           ^^^^^^^^^^^^^^^^^
  File "/Users/rexrealingojr./Library/CloudStorage/GoogleDrive-rex15realingo@gmail.com/My Drive/Ai/.venv/lib/python3.13/site-packages/telegram/ext/_utils/networkloop.py", line 108, in do_action
    return action_cb_task.result()
           ~~~~~~~~~~~~~~~~~~~~~^^
  File "/Users/rexrealingojr./Library/CloudStorage/GoogleDrive-rex15realingo@gmail.com/My Drive/Ai/.venv/lib/python3.13/site-packages/telegram/ext/_updater.py", line 340, in polling_action_cb
    updates = await self.bot.get_updates(
              ^^^^^^^^^^^^^^^^^^^^^^^^^^^
    ...<3 lines>...
    )
    ^
  File "/Users/rexrealingojr./Library/CloudStorage/GoogleDrive-rex15realingo@gmail.com/My Drive/Ai/.venv/lib/python3.13/site-packages/telegram/ext/_extbot.py", line 669, in get_updates
    updates = await super().get_updates(
              ^^^^^^^^^^^^^^^^^^^^^^^^^^
    ...<9 lines>...
    )
    ^
  File "/Users/rexrealingojr./Library/CloudStorage/GoogleDrive-rex15realingo@gmail.com/My Drive/Ai/.venv/lib/python3.13/site-packages/telegram/_bot.py", line 4610, in get_updates
    await self._post(
    ^^^^^^^^^^^^^^^^^
    ...<7 lines>...
    ),
    ^
  File "/Users/rexrealingojr./Library/CloudStorage/GoogleDrive-rex15realingo@gmail.com/My Drive/Ai/.venv/lib/python3.13/site-packages/telegram/_bot.py", line 697, in _post
    return await self._do_post(
           ^^^^^^^^^^^^^^^^^^^^
    ...<6 lines>...
    )
    ^
  File "/Users/rexrealingojr./Library/CloudStorage/GoogleDrive-rex15realingo@gmail.com/My Drive/Ai/.venv/lib/python3.13/site-packages/telegram/ext/_extbot.py", line 369, in _do_post
    return await super()._do_post(
           ^^^^^^^^^^^^^^^^^^^^^^^
    ...<6 lines>...
    )
    ^
  File "/Users/rexrealingojr./Library/CloudStorage/GoogleDrive-rex15realingo@gmail.com/My Drive/Ai/.venv/lib/python3.13/site-packages/telegram/_bot.py", line 726, in _do_post
    result = await request.post(
             ^^^^^^^^^^^^^^^^^^^
    ...<6 lines>...
    )
    ^
  File "/Users/rexrealingojr./Library/CloudStorage/GoogleDrive-rex15realingo@gmail.com/My Drive/Ai/.venv/lib/python3.13/site-packages/telegram/request/_baserequest.py", line 197, in post
    result = await self._request_wrapper(
             ^^^^^^^^^^^^^^^^^^^^^^^^^^^^
    ...<7 lines>...
    )
    ^
  File "/Users/rexrealingojr./Library/CloudStorage/GoogleDrive-rex15realingo@gmail.com/My Drive/Ai/.venv/lib/python3.13/site-packages/telegram/request/_baserequest.py", line 374, in _request_wrapper
    raise exception
telegram.error.Conflict: Conflict: terminated by other getUpdates request; make sure that only one bot instance is running
INFO:httpx:HTTP Request: POST https://api.telegram.org/bot7779786808:AAHul6zZde15UvoPbGb5aMm-KvtvROpqfB8/getUpdates "HTTP/1.1 409 Conflict"
ERROR:telegram.ext.Application:No error handlers are registered, logging exception.
Traceback (most recent call last):
  File "/Users/rexrealingojr./Library/CloudStorage/GoogleDrive-rex15realingo@gmail.com/My Drive/Ai/.venv/lib/python3.13/site-packages/telegram/ext/_utils/networkloop.py", line 115, in network_retry_loop
    if not await do_action():
           ^^^^^^^^^^^^^^^^^
  File "/Users/rexrealingojr./Library/CloudStorage/GoogleDrive-rex15realingo@gmail.com/My Drive/Ai/.venv/lib/python3.13/site-packages/telegram/ext/_utils/networkloop.py", line 108, in do_action
    return action_cb_task.result()
           ~~~~~~~~~~~~~~~~~~~~~^^
  File "/Users/rexrealingojr./Library/CloudStorage/GoogleDrive-rex15realingo@gmail.com/My Drive/Ai/.venv/lib/python3.13/site-packages/telegram/ext/_updater.py", line 340, in polling_action_cb
    updates = await self.bot.get_updates(
              ^^^^^^^^^^^^^^^^^^^^^^^^^^^
    ...<3 lines>...
    )
    ^
  File "/Users/rexrealingojr./Library/CloudStorage/GoogleDrive-rex15realingo@gmail.com/My Drive/Ai/.venv/lib/python3.13/site-packages/telegram/ext/_extbot.py", line 669, in get_updates
    updates = await super().get_updates(
              ^^^^^^^^^^^^^^^^^^^^^^^^^^
    ...<9 lines>...
    )
    ^
  File "/Users/rexrealingojr./Library/CloudStorage/GoogleDrive-rex15realingo@gmail.com/My Drive/Ai/.venv/lib/python3.13/site-packages/telegram/_bot.py", line 4610, in get_updates
    await self._post(
    ^^^^^^^^^^^^^^^^^
    ...<7 lines>...
    ),
    ^
  File "/Users/rexrealingojr./Library/CloudStorage/GoogleDrive-rex15realingo@gmail.com/My Drive/Ai/.venv/lib/python3.13/site-packages/telegram/_bot.py", line 697, in _post
    return await self._do_post(
           ^^^^^^^^^^^^^^^^^^^^
    ...<6 lines>...
    )
    ^
  File "/Users/rexrealingojr./Library/CloudStorage/GoogleDrive-rex15realingo@gmail.com/My Drive/Ai/.venv/lib/python3.13/site-packages/telegram/ext/_extbot.py", line 369, in _do_post
    return await super()._do_post(
           ^^^^^^^^^^^^^^^^^^^^^^^
    ...<6 lines>...
    )
    ^
  File "/Users/rexrealingojr./Library/CloudStorage/GoogleDrive-rex15realingo@gmail.com/My Drive/Ai/.venv/lib/python3.13/site-packages/telegram/_bot.py", line 726, in _do_post
    result = await request.post(
             ^^^^^^^^^^^^^^^^^^^
    ...<6 lines>...
    )
    ^
  File "/Users/rexrealingojr./Library/CloudStorage/GoogleDrive-rex15realingo@gmail.com/My Drive/Ai/.venv/lib/python3.13/site-packages/telegram/request/_baserequest.py", line 197, in post
    result = await self._request_wrapper(
             ^^^^^^^^^^^^^^^^^^^^^^^^^^^^
    ...<7 lines>...
    )
    ^
  File "/Users/rexrealingojr./Library/CloudStorage/GoogleDrive-rex15realingo@gmail.com/My Drive/Ai/.venv/lib/python3.13/site-packages/telegram/request/_baserequest.py", line 374, in _request_wrapper
    raise exception
telegram.error.Conflict: Conflict: terminated by other getUpdates request; make sure that only one bot instance is running
INFO:httpx:HTTP Request: POST https://api.telegram.org/bot7779786808:AAHul6zZde15UvoPbGb5aMm-KvtvROpqfB8/getUpdates "HTTP/1.1 409 Conflict"
ERROR:telegram.ext.Application:No error handlers are registered, logging exception.
Traceback (most recent call last):
  File "/Users/rexrealingojr./Library/CloudStorage/GoogleDrive-rex15realingo@gmail.com/My Drive/Ai/.venv/lib/python3.13/site-packages/telegram/ext/_utils/networkloop.py", line 115, in network_retry_loop
    if not await do_action():
           ^^^^^^^^^^^^^^^^^
  File "/Users/rexrealingojr./Library/CloudStorage/GoogleDrive-rex15realingo@gmail.com/My Drive/Ai/.venv/lib/python3.13/site-packages/telegram/ext/_utils/networkloop.py", line 108, in do_action
    return action_cb_task.result()
           ~~~~~~~~~~~~~~~~~~~~~^^
  File "/Users/rexrealingojr./Library/CloudStorage/GoogleDrive-rex15realingo@gmail.com/My Drive/Ai/.venv/lib/python3.13/site-packages/telegram/ext/_updater.py", line 340, in polling_action_cb
    updates = await self.bot.get_updates(
              ^^^^^^^^^^^^^^^^^^^^^^^^^^^
    ...<3 lines>...
    )
    ^
  File "/Users/rexrealingojr./Library/CloudStorage/GoogleDrive-rex15realingo@gmail.com/My Drive/Ai/.venv/lib/python3.13/site-packages/telegram/ext/_extbot.py", line 669, in get_updates
    updates = await super().get_updates(
              ^^^^^^^^^^^^^^^^^^^^^^^^^^
    ...<9 lines>...
    )
    ^
  File "/Users/rexrealingojr./Library/CloudStorage/GoogleDrive-rex15realingo@gmail.com/My Drive/Ai/.venv/lib/python3.13/site-packages/telegram/_bot.py", line 4610, in get_updates
    await self._post(
    ^^^^^^^^^^^^^^^^^
    ...<7 lines>...
    ),
    ^
  File "/Users/rexrealingojr./Library/CloudStorage/GoogleDrive-rex15realingo@gmail.com/My Drive/Ai/.venv/lib/python3.13/site-packages/telegram/_bot.py", line 697, in _post
    return await self._do_post(
           ^^^^^^^^^^^^^^^^^^^^
    ...<6 lines>...
    )
    ^
  File "/Users/rexrealingojr./Library/CloudStorage/GoogleDrive-rex15realingo@gmail.com/My Drive/Ai/.venv/lib/python3.13/site-packages/telegram/ext/_extbot.py", line 369, in _do_post
    return await super()._do_post(
           ^^^^^^^^^^^^^^^^^^^^^^^
    ...<6 lines>...
    )
    ^
  File "/Users/rexrealingojr./Library/CloudStorage/GoogleDrive-rex15realingo@gmail.com/My Drive/Ai/.venv/lib/python3.13/site-packages/telegram/_bot.py", line 726, in _do_post
    result = await request.post(
             ^^^^^^^^^^^^^^^^^^^
    ...<6 lines>...
    )
    ^
  File "/Users/rexrealingojr./Library/CloudStorage/GoogleDrive-rex15realingo@gmail.com/My Drive/Ai/.venv/lib/python3.13/site-packages/telegram/request/_baserequest.py", line 197, in post
    result = await self._request_wrapper(
             ^^^^^^^^^^^^^^^^^^^^^^^^^^^^
    ...<7 lines>...
    )
    ^
  File "/Users/rexrealingojr./Library/CloudStorage/GoogleDrive-rex15realingo@gmail.com/My Drive/Ai/.venv/lib/python3.13/site-packages/telegram/request/_baserequest.py", line 374, in _request_wrapper
    raise exception
telegram.error.Conflict: Conflict: terminated by other getUpdates request; make sure that only one bot instance is running
-rex15realingo@gmail.com/My Drive/Ai/.venv/lib/python3.13/site-packages/telegram/ext/_extbot.py", line 369, in _do_post
    return await super()._do_post(
           ^^^^^^^^^^^^^^^^^^^^^^^
    ...<6 lines>...
    )
    ^
  File "/Users/rexrealingojr./Library/CloudStorage/GoogleDrive-rex15realingo@gmail.com/My Drive/Ai/.venv/lib/python3.13/site-packages/telegram/_bot.py", line 726, in _do_post
    result = await request.post(
             ^^^^^^^^^^^^^^^^^^^
    ...<6 lines>...
    )
    ^
  File "/Users/rexrealingojr./Library/CloudStorage/GoogleDrive-rex15realingo@gmail.com/My Drive/Ai/.venv/lib/python3.13/site-packages/telegram/request/_baserequest.py", line 197, in post
    result = await self._request_wrapper(
             ^^^^^^^^^^^^^^^^^^^^^^^^^^^^
    ...<7 lines>...
    )
    ^
  File "/Users/rexrealingojr./Library/CloudStorage/GoogleDrive-rex15realingo@gmail.com/My Drive/Ai/.venv/lib/python3.13/site-packages/telegram/request/_baserequest.py", line 374, in _request_wrapper
    raise exception
telegram.error.Conflict: Conflict: terminated by other getUpdates request; make sure that only one bot instance is running
INFO:httpx:HTTP Request: POST https://api.telegram.org/bot7779786808:AAHul6zZde15UvoPbGb5aMm-KvtvROpqfB8/getUpdates "HTTP/1.1 409 Conflict"
ERROR:telegram.ext.Application:No error handlers are registered, logging exception.
Traceback (most recent call last):
  File "/Users/rexrealingojr./Library/CloudStorage/GoogleDrive-rex15realingo@gmail.com/My Drive/Ai/.venv/lib/python3.13/site-packages/telegram/ext/_utils/networkloop.py", line 115, in network_retry_loop
    if not await do_action():
           ^^^^^^^^^^^^^^^^^
  File "/Users/rexrealingojr./Library/CloudStorage/GoogleDrive-rex15realingo@gmail.com/My Drive/Ai/.venv/lib/python3.13/site-packages/telegram/ext/_utils/networkloop.py", line 108, in do_action
    return action_cb_task.result()
           ~~~~~~~~~~~~~~~~~~~~~^^
  File "/Users/rexrealingojr./Library/CloudStorage/GoogleDrive-rex15realingo@gmail.com/My Drive/Ai/.venv/lib/python3.13/site-packages/telegram/ext/_updater.py", line 340, in polling_action_cb
    updates = await self.bot.get_updates(
              ^^^^^^^^^^^^^^^^^^^^^^^^^^^
    ...<3 lines>...
    )
    ^
  File "/Users/rexrealingojr./Library/CloudStorage/GoogleDrive-rex15realingo@gmail.com/My Drive/Ai/.venv/lib/python3.13/site-packages/telegram/ext/_extbot.py", line 669, in get_updates
    updates = await super().get_updates(
              ^^^^^^^^^^^^^^^^^^^^^^^^^^
    ...<9 lines>...
    )
    ^
  File "/Users/rexrealingojr./Library/CloudStorage/GoogleDrive-rex15realingo@gmail.com/My Drive/Ai/.venv/lib/python3.13/site-packages/telegram/_bot.py", line 4610, in get_updates
    await self._post(
    ^^^^^^^^^^^^^^^^^
    ...<7 lines>...
    ),
    ^
  File "/Users/rexrealingojr./Library/CloudStorage/GoogleDrive-rex15realingo@gmail.com/My Drive/Ai/.venv/lib/python3.13/site-packages/telegram/_bot.py", line 697, in _post
    return await self._do_post(
           ^^^^^^^^^^^^^^^^^^^^
    ...<6 lines>...
    )
    ^
  File "/Users/rexrealingojr./Library/CloudStorage/GoogleDrive-rex15realingo@gmail.com/My Drive/Ai/.venv/lib/python3.13/site-packages/telegram/ext/_extbot.py", line 369, in _do_post
    return await super()._do_post(
           ^^^^^^^^^^^^^^^^^^^^^^^
    ...<6 lines>...
    )
    ^
  File "/Users/rexrealingojr./Library/CloudStorage/GoogleDrive-rex15realingo@gmail.com/My Drive/Ai/.venv/lib/python3.13/site-packages/telegram/_bot.py", line 726, in _do_post
    result = await request.post(
             ^^^^^^^^^^^^^^^^^^^
    ...<6 lines>...
    )
    ^
  File "/Users/rexrealingojr./Library/CloudStorage/GoogleDrive-rex15realingo@gmail.com/My Drive/Ai/.venv/lib/python3.13/site-packages/telegram/request/_baserequest.py", line 197, in post
    result = await self._request_wrapper(
             ^^^^^^^^^^^^^^^^^^^^^^^^^^^^
    ...<7 lines>...
    )
    ^
  File "/Users/rexrealingojr./Library/CloudStorage/GoogleDrive-rex15realingo@gmail.com/My Drive/Ai/.venv/lib/python3.13/site-packages/telegram/request/_baserequest.py", line 374, in _request_wrapper
    raise exception
telegram.error.Conflict: Conflict: terminated by other getUpdates request; make sure that only one bot instance is running
INFO:httpx:HTTP Request: POST https://api.telegram.org/bot7779786808:AAHul6zZde15UvoPbGb5aMm-KvtvROpqfB8/getUpdates "HTTP/1.1 409 Conflict"
ERROR:telegram.ext.Application:No error handlers are registered, logging exception.
Traceback (most recent call last):
  File "/Users/rexrealingojr./Library/CloudStorage/GoogleDrive-rex15realingo@gmail.com/My Drive/Ai/.venv/lib/python3.13/site-packages/telegram/ext/_utils/networkloop.py", line 115, in network_retry_loop
    if not await do_action():
           ^^^^^^^^^^^^^^^^^
  File "/Users/rexrealingojr./Library/CloudStorage/GoogleDrive-rex15realingo@gmail.com/My Drive/Ai/.venv/lib/python3.13/site-packages/telegram/ext/_utils/networkloop.py", line 108, in do_action
    return action_cb_task.result()
           ~~~~~~~~~~~~~~~~~~~~~^^
  File "/Users/rexrealingojr./Library/CloudStorage/GoogleDrive-rex15realingo@gmail.com/My Drive/Ai/.venv/lib/python3.13/site-packages/telegram/ext/_updater.py", line 340, in polling_action_cb
    updates = await self.bot.get_updates(
              ^^^^^^^^^^^^^^^^^^^^^^^^^^^
    ...<3 lines>...
    )
    ^
  File "/Users/rexrealingojr./Library/CloudStorage/GoogleDrive-rex15realingo@gmail.com/My Drive/Ai/.venv/lib/python3.13/site-packages/telegram/ext/_extbot.py", line 669, in get_updates
    updates = await super().get_updates(
              ^^^^^^^^^^^^^^^^^^^^^^^^^^
    ...<9 lines>...
    )
    ^
  File "/Users/rexrealingojr./Library/CloudStorage/GoogleDrive-rex15realingo@gmail.com/My Drive/Ai/.venv/lib/python3.13/site-packages/telegram/_bot.py", line 4610, in get_updates
    await self._post(
    ^^^^^^^^^^^^^^^^^
    ...<7 lines>...
    ),
    ^
  File "/Users/rexrealingojr./Library/CloudStorage/GoogleDrive-rex15realingo@gmail.com/My Drive/Ai/.venv/lib/python3.13/site-packages/telegram/_bot.py", line 697, in _post
    return await self._do_post(
           ^^^^^^^^^^^^^^^^^^^^
    ...<6 lines>...
    )
    ^
  File "/Users/rexrealingojr./Library/CloudStorage/GoogleDrive-rex15realingo@gmail.com/My Drive/Ai/.venv/lib/python3.13/site-packages/telegram/ext/_extbot.py", line 369, in _do_post
    return await super()._do_post(
           ^^^^^^^^^^^^^^^^^^^^^^^
    ...<6 lines>...
    )
    ^
  File "/Users/rexrealingojr./Library/CloudStorage/GoogleDrive-rex15realingo@gmail.com/My Drive/Ai/.venv/lib/python3.13/site-packages/telegram/_bot.py", line 726, in _do_post
    result = await request.post(
             ^^^^^^^^^^^^^^^^^^^
    ...<6 lines>...
    )
    ^
  File "/Users/rexrealingojr./Library/CloudStorage/GoogleDrive-rex15realingo@gmail.com/My Drive/Ai/.venv/lib/python3.13/site-packages/telegram/request/_baserequest.py", line 197, in post
    result = await self._request_wrapper(
             ^^^^^^^^^^^^^^^^^^^^^^^^^^^^
    ...<7 lines>...
    )
    ^
  File "/Users/rexrealingojr./Library/CloudStorage/GoogleDrive-rex15realingo@gmail.com/My Drive/Ai/.venv/lib/python3.13/site-packages/telegram/request/_baserequest.py", line 374, in _request_wrapper
    raise exception
telegram.error.Conflict: Conflict: terminated by other getUpdates request; make sure that only one bot instance is running
INFO:httpx:HTTP Request: POST https://api.telegram.org/bot7779786808:AAHul6zZde15UvoPbGb5aMm-KvtvROpqfB8/getUpdates "HTTP/1.1 409 Conflict"
ERROR:telegram.ext.Application:No error handlers are registered, logging exception.
Traceback (most recent call last):
  File "/Users/rexrealingojr./Library/CloudStorage/GoogleDrive-rex15realingo@gmail.com/My Drive/Ai/.venv/lib/python3.13/site-packages/telegram/ext/_utils/networkloop.py", line 115, in network_retry_loop
    if not await do_action():
           ^^^^^^^^^^^^^^^^^
  File "/Users/rexrealingojr./Library/CloudStorage/GoogleDrive-rex15realingo@gmail.com/My Drive/Ai/.venv/lib/python3.13/site-packages/telegram/ext/_utils/networkloop.py", line 108, in do_action
    return action_cb_task.result()
           ~~~~~~~~~~~~~~~~~~~~~^^
  File "/Users/rexrealingojr./Library/CloudStorage/GoogleDrive-rex15realingo@gmail.com/My Drive/Ai/.venv/lib/python3.13/site-packages/telegram/ext/_updater.py", line 340, in polling_action_cb
    updates = await self.bot.get_updates(
              ^^^^^^^^^^^^^^^^^^^^^^^^^^^
    ...<3 lines>...
    )
    ^
  File "/Users/rexrealingojr./Library/CloudStorage/GoogleDrive-rex15realingo@gmail.com/My Drive/Ai/.venv/lib/python3.13/site-packages/telegram/ext/_extbot.py", line 669, in get_updates
    updates = await super().get_updates(
              ^^^^^^^^^^^^^^^^^^^^^^^^^^
    ...<9 lines>...
    )
    ^
  File "/Users/rexrealingojr./Library/CloudStorage/GoogleDrive-rex15realingo@gmail.com/My Drive/Ai/.venv/lib/python3.13/site-packages/telegram/_bot.py", line 4610, in get_updates
    await self._post(
    ^^^^^^^^^^^^^^^^^
    ...<7 lines>...
    ),
    ^
  File "/Users/rexrealingojr./Library/CloudStorage/GoogleDrive-rex15realingo@gmail.com/My Drive/Ai/.venv/lib/python3.13/site-packages/telegram/_bot.py", line 697, in _post
    return await self._do_post(
           ^^^^^^^^^^^^^^^^^^^^
    ...<6 lines>...
    )
    ^
  File "/Users/rexrealingojr./Library/CloudStorage/GoogleDrive-rex15realingo@gmail.com/My Drive/Ai/.venv/lib/python3.13/site-packages/telegram/ext/_extbot.py", line 369, in _do_post
    return await super()._do_post(
           ^^^^^^^^^^^^^^^^^^^^^^^
    ...<6 lines>...
    )
    ^
  File "/Users/rexrealingojr./Library/CloudStorage/GoogleDrive-rex15realingo@gmail.com/My Drive/Ai/.venv/lib/python3.13/site-packages/telegram/_bot.py", line 726, in _do_post
    result = await request.post(
             ^^^^^^^^^^^^^^^^^^^
    ...<6 lines>...
    )
    ^
  File "/Users/rexrealingojr./Library/CloudStorage/GoogleDrive-rex15realingo@gmail.com/My Drive/Ai/.venv/lib/python3.13/site-packages/telegram/request/_baserequest.py", line 197, in post
    result = await self._request_wrapper(
             ^^^^^^^^^^^^^^^^^^^^^^^^^^^^
    ...<7 lines>...
    )
    ^
  File "/Users/rexrealingojr./Library/CloudStorage/GoogleDrive-rex15realingo@gmail.com/My Drive/Ai/.venv/lib/python3.13/site-packages/telegram/request/_baserequest.py", line 374, in _request_wrapper
    raise exception
telegram.error.Conflict: Conflict: terminated by other getUpdates request; make sure that only one bot instance is running
INFO:httpx:HTTP Request: POST https://api.telegram.org/bot7779786808:AAHul6zZde15UvoPbGb5aMm-KvtvROpqfB8/getUpdates "HTTP/1.1 200 OK"
INFO:httpx:HTTP Request: POST https://api.telegram.org/bot7779786808:AAHul6zZde15UvoPbGb5aMm-KvtvROpqfB8/sendMessage "HTTP/1.1 200 OK"
ERROR:telegram.ext.Application:No error handlers are registered, logging exception.
Traceback (most recent call last):
  File "/Users/rexrealingojr./Library/CloudStorage/GoogleDrive-rex15realingo@gmail.com/My Drive/Ai/.venv/lib/python3.13/site-packages/telegram/ext/_application.py", line 1309, in process_update
    await coroutine
  File "/Users/rexrealingojr./Library/CloudStorage/GoogleDrive-rex15realingo@gmail.com/My Drive/Ai/.venv/lib/python3.13/site-packages/telegram/ext/_handlers/basehandler.py", line 158, in handle_update
    return await self.callback(update, context)
           ^^^^^^^^^^^^^^^^^^^^^^^^^^^^^^^^^^^^
  File "/Users/rexrealingojr./Library/CloudStorage/GoogleDrive-rex15realingo@gmail.com/My Drive/Ai/handlers/commands.py", line 13, in start_command
    await menu_command(update, context)
  File "/Users/rexrealingojr./Library/CloudStorage/GoogleDrive-rex15realingo@gmail.com/My Drive/Ai/handlers/commands.py", line 27, in menu_command
    ]
    
  File "/Users/rexrealingojr./Library/CloudStorage/GoogleDrive-rex15realingo@gmail.com/My Drive/Ai/.venv/lib/python3.13/site-packages/telegram/_inline/inlinekeyboardmarkup.py", line 80, in __init__
    raise ValueError(
    ...<2 lines>...
    )
ValueError: The parameter `inline_keyboard` should be a sequence of sequences of InlineKeyboardButtons
INFO:httpx:HTTP Request: POST https://api.telegram.org/bot7779786808:AAHul6zZde15UvoPbGb5aMm-KvtvROpqfB8/getUpdates "HTTP/1.1 200 OK"
INFO:httpx:HTTP Request: POST https://api.telegram.org/bot7779786808:AAHul6zZde15UvoPbGb5aMm-KvtvROpqfB8/sendMessage "HTTP/1.1 200 OK"
ERROR:telegram.ext.Application:No error handlers are registered, logging exception.
Traceback (most recent call last):
  File "/Users/rexrealingojr./Library/CloudStorage/GoogleDrive-rex15realingo@gmail.com/My Drive/Ai/.venv/lib/python3.13/site-packages/telegram/ext/_application.py", line 1309, in process_update
    await coroutine
  File "/Users/rexrealingojr./Library/CloudStorage/GoogleDrive-rex15realingo@gmail.com/My Drive/Ai/.venv/lib/python3.13/site-packages/telegram/ext/_handlers/basehandler.py", line 158, in handle_update
    return await self.callback(update, context)
           ^^^^^^^^^^^^^^^^^^^^^^^^^^^^^^^^^^^^
  File "/Users/rexrealingojr./Library/CloudStorage/GoogleDrive-rex15realingo@gmail.com/My Drive/Ai/handlers/commands.py", line 13, in start_command
    await menu_command(update, context)
  File "/Users/rexrealingojr./Library/CloudStorage/GoogleDrive-rex15realingo@gmail.com/My Drive/Ai/handlers/commands.py", line 27, in menu_command
    ]
    
  File "/Users/rexrealingojr./Library/CloudStorage/GoogleDrive-rex15realingo@gmail.com/My Drive/Ai/.venv/lib/python3.13/site-packages/telegram/_inline/inlinekeyboardmarkup.py", line 80, in __init__
    raise ValueError(
    ...<2 lines>...
    )
ValueError: The parameter `inline_keyboard` should be a sequence of sequences of InlineKeyboardButtons
INFO:httpx:HTTP Request: POST https://api.telegram.org/bot7779786808:AAHul6zZde15UvoPbGb5aMm-KvtvROpqfB8/getUpdates "HTTP/1.1 409 Conflict"
ERROR:telegram.ext.Application:No error handlers are registered, logging exception.
Traceback (most recent call last):
  File "/Users/rexrealingojr./Library/CloudStorage/GoogleDrive-rex15realingo@gmail.com/My Drive/Ai/.venv/lib/python3.13/site-packages/telegram/ext/_utils/networkloop.py", line 115, in network_retry_loop
    if not await do_action():
           ^^^^^^^^^^^^^^^^^
  File "/Users/rexrealingojr./Library/CloudStorage/GoogleDrive-rex15realingo@gmail.com/My Drive/Ai/.venv/lib/python3.13/site-packages/telegram/ext/_utils/networkloop.py", line 108, in do_action
    return action_cb_task.result()
           ~~~~~~~~~~~~~~~~~~~~~^^
  File "/Users/rexrealingojr./Library/CloudStorage/GoogleDrive-rex15realingo@gmail.com/My Drive/Ai/.venv/lib/python3.13/site-packages/telegram/ext/_updater.py", line 340, in polling_action_cb
    updates = await self.bot.get_updates(
              ^^^^^^^^^^^^^^^^^^^^^^^^^^^
    ...<3 lines>...
    )
    ^
  File "/Users/rexrealingojr./Library/CloudStorage/GoogleDrive-rex15realingo@gmail.com/My Drive/Ai/.venv/lib/python3.13/site-packages/telegram/ext/_extbot.py", line 669, in get_updates
    updates = await super().get_updates(
              ^^^^^^^^^^^^^^^^^^^^^^^^^^
    ...<9 lines>...
    )
    ^
  File "/Users/rexrealingojr./Library/CloudStorage/GoogleDrive-rex15realingo@gmail.com/My Drive/Ai/.venv/lib/python3.13/site-packages/telegram/_bot.py", line 4610, in get_updates
    await self._post(
    ^^^^^^^^^^^^^^^^^
    ...<7 lines>...
    ),
    ^
  File "/Users/rexrealingojr./Library/CloudStorage/GoogleDrive-rex15realingo@gmail.com/My Drive/Ai/.venv/lib/python3.13/site-packages/telegram/_bot.py", line 697, in _post
    return await self._do_post(
           ^^^^^^^^^^^^^^^^^^^^
    ...<6 lines>...
    )
    ^
  File "/Users/rexrealingojr./Library/CloudStorage/GoogleDrive-rex15realingo@gmail.com/My Drive/Ai/.venv/lib/python3.13/site-packages/telegram/ext/_extbot.py", line 369, in _do_post
    return await super()._do_post(
           ^^^^^^^^^^^^^^^^^^^^^^^
    ...<6 lines>...
    )
    ^
  File "/Users/rexrealingojr./Library/CloudStorage/GoogleDrive-rex15realingo@gmail.com/My Drive/Ai/.venv/lib/python3.13/site-packages/telegram/_bot.py", line 726, in _do_post
    result = await request.post(
             ^^^^^^^^^^^^^^^^^^^
    ...<6 lines>...
    )
    ^
  File "/Users/rexrealingojr./Library/CloudStorage/GoogleDrive-rex15realingo@gmail.com/My Drive/Ai/.venv/lib/python3.13/site-packages/telegram/request/_baserequest.py", line 197, in post
    result = await self._request_wrapper(
             ^^^^^^^^^^^^^^^^^^^^^^^^^^^^
    ...<7 lines>...
    )
    ^
  File "/Users/rexrealingojr./Library/CloudStorage/GoogleDrive-rex15realingo@gmail.com/My Drive/Ai/.venv/lib/python3.13/site-packages/telegram/request/_baserequest.py", line 374, in _request_wrapper
    raise exception
telegram.error.Conflict: Conflict: terminated by other getUpdates request; make sure that only one bot instance is running
INFO:httpx:HTTP Request: POST https://api.telegram.org/bot7779786808:AAHul6zZde15UvoPbGb5aMm-KvtvROpqfB8/getUpdates "HTTP/1.1 200 OK"
INFO:httpx:HTTP Request: POST https://api.telegram.org/bot7779786808:AAHul6zZde15UvoPbGb5aMm-KvtvROpqfB8/sendMessage "HTTP/1.1 200 OK"
ERROR:telegram.ext.Application:No error handlers are registered, logging exception.
Traceback (most recent call last):
  File "/Users/rexrealingojr./Library/CloudStorage/GoogleDrive-rex15realingo@gmail.com/My Drive/Ai/.venv/lib/python3.13/site-packages/telegram/ext/_application.py", line 1309, in process_update
    await coroutine
  File "/Users/rexrealingojr./Library/CloudStorage/GoogleDrive-rex15realingo@gmail.com/My Drive/Ai/.venv/lib/python3.13/site-packages/telegram/ext/_handlers/basehandler.py", line 158, in handle_update
    return await self.callback(update, context)
           ^^^^^^^^^^^^^^^^^^^^^^^^^^^^^^^^^^^^
  File "/Users/rexrealingojr./Library/CloudStorage/GoogleDrive-rex15realingo@gmail.com/My Drive/Ai/handlers/commands.py", line 13, in start_command
    await menu_command(update, context)
  File "/Users/rexrealingojr./Library/CloudStorage/GoogleDrive-rex15realingo@gmail.com/My Drive/Ai/handlers/commands.py", line 27, in menu_command
    ]
    
  File "/Users/rexrealingojr./Library/CloudStorage/GoogleDrive-rex15realingo@gmail.com/My Drive/Ai/.venv/lib/python3.13/site-packages/telegram/_inline/inlinekeyboardmarkup.py", line 80, in __init__
    raise ValueError(
    ...<2 lines>...
    )
ValueError: The parameter `inline_keyboard` should be a sequence of sequences of InlineKeyboardButtons
INFO:httpx:HTTP Request: POST https://api.telegram.org/bot7779786808:AAHul6zZde15UvoPbGb5aMm-KvtvROpqfB8/getUpdates "HTTP/1.1 409 Conflict"
ERROR:telegram.ext.Application:No error handlers are registered, logging exception.
Traceback (most recent call last):
  File "/Users/rexrealingojr./Library/CloudStorage/GoogleDrive-rex15realingo@gmail.com/My Drive/Ai/.venv/lib/python3.13/site-packages/telegram/ext/_utils/networkloop.py", line 115, in network_retry_loop
    if not await do_action():
           ^^^^^^^^^^^^^^^^^
  File "/Users/rexrealingojr./Library/CloudStorage/GoogleDrive-rex15realingo@gmail.com/My Drive/Ai/.venv/lib/python3.13/site-packages/telegram/ext/_utils/networkloop.py", line 108, in do_action
    return action_cb_task.result()
           ~~~~~~~~~~~~~~~~~~~~~^^
  File "/Users/rexrealingojr./Library/CloudStorage/GoogleDrive-rex15realingo@gmail.com/My Drive/Ai/.venv/lib/python3.13/site-packages/telegram/ext/_updater.py", line 340, in polling_action_cb
    updates = await self.bot.get_updates(
              ^^^^^^^^^^^^^^^^^^^^^^^^^^^
    ...<3 lines>...
    )
    ^
  File "/Users/rexrealingojr./Library/CloudStorage/GoogleDrive-rex15realingo@gmail.com/My Drive/Ai/.venv/lib/python3.13/site-packages/telegram/ext/_extbot.py", line 669, in get_updates
    updates = await super().get_updates(
              ^^^^^^^^^^^^^^^^^^^^^^^^^^
    ...<9 lines>...
    )
    ^
  File "/Users/rexrealingojr./Library/CloudStorage/GoogleDrive-rex15realingo@gmail.com/My Drive/Ai/.venv/lib/python3.13/site-packages/telegram/_bot.py", line 4610, in get_updates
    await self._post(
    ^^^^^^^^^^^^^^^^^
    ...<7 lines>...
    ),
    ^
  File "/Users/rexrealingojr./Library/CloudStorage/GoogleDrive-rex15realingo@gmail.com/My Drive/Ai/.venv/lib/python3.13/site-packages/telegram/_bot.py", line 697, in _post
    return await self._do_post(
           ^^^^^^^^^^^^^^^^^^^^
    ...<6 lines>...
    )
    ^
  File "/Users/rexrealingojr./Library/CloudStorage/GoogleDrive-rex15realingo@gmail.com/My Drive/Ai/.venv/lib/python3.13/site-packages/telegram/ext/_extbot.py", line 369, in _do_post
    return await super()._do_post(
           ^^^^^^^^^^^^^^^^^^^^^^^
    ...<6 lines>...
    )
    ^
  File "/Users/rexrealingojr./Library/CloudStorage/GoogleDrive-rex15realingo@gmail.com/My Drive/Ai/.venv/lib/python3.13/site-packages/telegram/_bot.py", line 726, in _do_post
    result = await request.post(
             ^^^^^^^^^^^^^^^^^^^
    ...<6 lines>...
    )
    ^
  File "/Users/rexrealingojr./Library/CloudStorage/GoogleDrive-rex15realingo@gmail.com/My Drive/Ai/.venv/lib/python3.13/site-packages/telegram/request/_baserequest.py", line 197, in post
    result = await self._request_wrapper(
             ^^^^^^^^^^^^^^^^^^^^^^^^^^^^
    ...<7 lines>...
    )
    ^
  File "/Users/rexrealingojr./Library/CloudStorage/GoogleDrive-rex15realingo@gmail.com/My Drive/Ai/.venv/lib/python3.13/site-packages/telegram/request/_baserequest.py", line 374, in _request_wrapper
    raise exception
telegram.error.Conflict: Conflict: terminated by other getUpdates request; make sure that only one bot instance is running
INFO:httpx:HTTP Request: POST https://api.telegram.org/bot7779786808:AAHul6zZde15UvoPbGb5aMm-KvtvROpqfB8/getUpdates "HTTP/1.1 200 OK"
INFO:httpx:HTTP Request: POST https://api.telegram.org/bot7779786808:AAHul6zZde15UvoPbGb5aMm-KvtvROpqfB8/sendMessage "HTTP/1.1 200 OK"
ERROR:telegram.ext.Application:No error handlers are registered, logging exception.
Traceback (most recent call last):
  File "/Users/rexrealingojr./Library/CloudStorage/GoogleDrive-rex15realingo@gmail.com/My Drive/Ai/.venv/lib/python3.13/site-packages/telegram/ext/_application.py", line 1309, in process_update
    await coroutine
  File "/Users/rexrealingojr./Library/CloudStorage/GoogleDrive-rex15realingo@gmail.com/My Drive/Ai/.venv/lib/python3.13/site-packages/telegram/ext/_handlers/basehandler.py", line 158, in handle_update
    return await self.callback(update, context)
           ^^^^^^^^^^^^^^^^^^^^^^^^^^^^^^^^^^^^
  File "/Users/rexrealingojr./Library/CloudStorage/GoogleDrive-rex15realingo@gmail.com/My Drive/Ai/handlers/commands.py", line 13, in start_command
    await menu_command(update, context)
  File "/Users/rexrealingojr./Library/CloudStorage/GoogleDrive-rex15realingo@gmail.com/My Drive/Ai/handlers/commands.py", line 27, in menu_command
    ]
    
  File "/Users/rexrealingojr./Library/CloudStorage/GoogleDrive-rex15realingo@gmail.com/My Drive/Ai/.venv/lib/python3.13/site-packages/telegram/_inline/inlinekeyboardmarkup.py", line 80, in __init__
    raise ValueError(
    ...<2 lines>...
    )
ValueError: The parameter `inline_keyboard` should be a sequence of sequences of InlineKeyboardButtons
INFO:httpx:HTTP Request: POST https://api.telegram.org/bot7779786808:AAHul6zZde15UvoPbGb5aMm-KvtvROpqfB8/getUpdates "HTTP/1.1 409 Conflict"
ERROR:telegram.ext.Application:No error handlers are registered, logging exception.
Traceback (most recent call last):
  File "/Users/rexrealingojr./Library/CloudStorage/GoogleDrive-rex15realingo@gmail.com/My Drive/Ai/.venv/lib/python3.13/site-packages/telegram/ext/_utils/networkloop.py", line 115, in network_retry_loop
    if not await do_action():
           ^^^^^^^^^^^^^^^^^
  File "/Users/rexrealingojr./Library/CloudStorage/GoogleDrive-rex15realingo@gmail.com/My Drive/Ai/.venv/lib/python3.13/site-packages/telegram/ext/_utils/networkloop.py", line 108, in do_action
    return action_cb_task.result()
           ~~~~~~~~~~~~~~~~~~~~~^^
  File "/Users/rexrealingojr./Library/CloudStorage/GoogleDrive-rex15realingo@gmail.com/My Drive/Ai/.venv/lib/python3.13/site-packages/telegram/ext/_updater.py", line 340, in polling_action_cb
    updates = await self.bot.get_updates(
              ^^^^^^^^^^^^^^^^^^^^^^^^^^^
    ...<3 lines>...
    )
    ^
  File "/Users/rexrealingojr./Library/CloudStorage/GoogleDrive-rex15realingo@gmail.com/My Drive/Ai/.venv/lib/python3.13/site-packages/telegram/ext/_extbot.py", line 669, in get_updates
    updates = await super().get_updates(
              ^^^^^^^^^^^^^^^^^^^^^^^^^^
    ...<9 lines>...
    )
    ^
  File "/Users/rexrealingojr./Library/CloudStorage/GoogleDrive-rex15realingo@gmail.com/My Drive/Ai/.venv/lib/python3.13/site-packages/telegram/_bot.py", line 4610, in get_updates
    await self._post(
    ^^^^^^^^^^^^^^^^^
    ...<7 lines>...
    ),
    ^
  File "/Users/rexrealingojr./Library/CloudStorage/GoogleDrive-rex15realingo@gmail.com/My Drive/Ai/.venv/lib/python3.13/site-packages/telegram/_bot.py", line 697, in _post
    return await self._do_post(
           ^^^^^^^^^^^^^^^^^^^^
    ...<6 lines>...
    )
    ^
  File "/Users/rexrealingojr./Library/CloudStorage/GoogleDrive-rex15realingo@gmail.com/My Drive/Ai/.venv/lib/python3.13/site-packages/telegram/ext/_extbot.py", line 369, in _do_post
    return await super()._do_post(
           ^^^^^^^^^^^^^^^^^^^^^^^
    ...<6 lines>...
    )
    ^
  File "/Users/rexrealingojr./Library/CloudStorage/GoogleDrive-rex15realingo@gmail.com/My Drive/Ai/.venv/lib/python3.13/site-packages/telegram/_bot.py", line 726, in _do_post
    result = await request.post(
             ^^^^^^^^^^^^^^^^^^^
    ...<6 lines>...
    )
    ^
  File "/Users/rexrealingojr./Library/CloudStorage/GoogleDrive-rex15realingo@gmail.com/My Drive/Ai/.venv/lib/python3.13/site-packages/telegram/request/_baserequest.py", line 197, in post
    result = await self._request_wrapper(
             ^^^^^^^^^^^^^^^^^^^^^^^^^^^^
    ...<7 lines>...
    )
    ^
  File "/Users/rexrealingojr./Library/CloudStorage/GoogleDrive-rex15realingo@gmail.com/My Drive/Ai/.venv/lib/python3.13/site-packages/telegram/request/_baserequest.py", line 374, in _request_wrapper
    raise exception
telegram.error.Conflict: Conflict: terminated by other getUpdates request; make sure that only one bot instance is running
INFO:httpx:HTTP Request: POST https://api.telegram.org/bot7779786808:AAHul6zZde15UvoPbGb5aMm-KvtvROpqfB8/getUpdates "HTTP/1.1 200 OK"
INFO:httpx:HTTP Request: POST https://api.telegram.org/bot7779786808:AAHul6zZde15UvoPbGb5aMm-KvtvROpqfB8/sendMessage "HTTP/1.1 200 OK"
ERROR:telegram.ext.Application:No error handlers are registered, logging exception.
Traceback (most recent call last):
  File "/Users/rexrealingojr./Library/CloudStorage/GoogleDrive-rex15realingo@gmail.com/My Drive/Ai/.venv/lib/python3.13/site-packages/telegram/ext/_application.py", line 1309, in process_update
    await coroutine
  File "/Users/rexrealingojr./Library/CloudStorage/GoogleDrive-rex15realingo@gmail.com/My Drive/Ai/.venv/lib/python3.13/site-packages/telegram/ext/_handlers/basehandler.py", line 158, in handle_update
    return await self.callback(update, context)
           ^^^^^^^^^^^^^^^^^^^^^^^^^^^^^^^^^^^^
  File "/Users/rexrealingojr./Library/CloudStorage/GoogleDrive-rex15realingo@gmail.com/My Drive/Ai/handlers/commands.py", line 13, in start_command
    await menu_command(update, context)
  File "/Users/rexrealingojr./Library/CloudStorage/GoogleDrive-rex15realingo@gmail.com/My Drive/Ai/handlers/commands.py", line 27, in menu_command
    ]
    
  File "/Users/rexrealingojr./Library/CloudStorage/GoogleDrive-rex15realingo@gmail.com/My Drive/Ai/.venv/lib/python3.13/site-packages/telegram/_inline/inlinekeyboardmarkup.py", line 80, in __init__
    raise ValueError(
    ...<2 lines>...
    )
ValueError: The parameter `inline_keyboard` should be a sequence of sequences of InlineKeyboardButtons
INFO:httpx:HTTP Request: POST https://api.telegram.org/bot7779786808:AAHul6zZde15UvoPbGb5aMm-KvtvROpqfB8/getUpdates "HTTP/1.1 200 OK"
INFO:httpx:HTTP Request: POST https://api.telegram.org/bot7779786808:AAHul6zZde15UvoPbGb5aMm-KvtvROpqfB8/getUpdates "HTTP/1.1 200 OK"
INFO:httpx:HTTP Request: POST https://api.telegram.org/bot7779786808:AAHul6zZde15UvoPbGb5aMm-KvtvROpqfB8/sendMessage "HTTP/1.1 200 OK"
ERROR:telegram.ext.Application:No error handlers are registered, logging exception.
Traceback (most recent call last):
  File "/Users/rexrealingojr./Library/CloudStorage/GoogleDrive-rex15realingo@gmail.com/My Drive/Ai/.venv/lib/python3.13/site-packages/telegram/ext/_application.py", line 1309, in process_update
    await coroutine
  File "/Users/rexrealingojr./Library/CloudStorage/GoogleDrive-rex15realingo@gmail.com/My Drive/Ai/.venv/lib/python3.13/site-packages/telegram/ext/_handlers/basehandler.py", line 158, in handle_update
    return await self.callback(update, context)
           ^^^^^^^^^^^^^^^^^^^^^^^^^^^^^^^^^^^^
  File "/Users/rexrealingojr./Library/CloudStorage/GoogleDrive-rex15realingo@gmail.com/My Drive/Ai/handlers/commands.py", line 13, in start_command
    await menu_command(update, context)
  File "/Users/rexrealingojr./Library/CloudStorage/GoogleDrive-rex15realingo@gmail.com/My Drive/Ai/handlers/commands.py", line 27, in menu_command
    ]
    
  File "/Users/rexrealingojr./Library/CloudStorage/GoogleDrive-rex15realingo@gmail.com/My Drive/Ai/.venv/lib/python3.13/site-packages/telegram/_inline/inlinekeyboardmarkup.py", line 80, in __init__
    raise ValueError(
    ...<2 lines>...
    )
ValueError: The parameter `inline_keyboard` should be a sequence of sequences of InlineKeyboardButtons
INFO:httpx:HTTP Request: POST https://api.telegram.org/bot7779786808:AAHul6zZde15UvoPbGb5aMm-KvtvROpqfB8/getUpdates "HTTP/1.1 409 Conflict"
ERROR:telegram.ext.Application:No error handlers are registered, logging exception.
Traceback (most recent call last):
  File "/Users/rexrealingojr./Library/CloudStorage/GoogleDrive-rex15realingo@gmail.com/My Drive/Ai/.venv/lib/python3.13/site-packages/telegram/ext/_utils/networkloop.py", line 115, in network_retry_loop
    if not await do_action():
           ^^^^^^^^^^^^^^^^^
  File "/Users/rexrealingojr./Library/CloudStorage/GoogleDrive-rex15realingo@gmail.com/My Drive/Ai/.venv/lib/python3.13/site-packages/telegram/ext/_utils/networkloop.py", line 108, in do_action
    return action_cb_task.result()
           ~~~~~~~~~~~~~~~~~~~~~^^
  File "/Users/rexrealingojr./Library/CloudStorage/GoogleDrive-rex15realingo@gmail.com/My Drive/Ai/.venv/lib/python3.13/site-packages/telegram/ext/_updater.py", line 340, in polling_action_cb
    updates = await self.bot.get_updates(
              ^^^^^^^^^^^^^^^^^^^^^^^^^^^
    ...<3 lines>...
    )
    ^
  File "/Users/rexrealingojr./Library/CloudStorage/GoogleDrive-rex15realingo@gmail.com/My Drive/Ai/.venv/lib/python3.13/site-packages/telegram/ext/_extbot.py", line 669, in get_updates
    updates = await super().get_updates(
              ^^^^^^^^^^^^^^^^^^^^^^^^^^
    ...<9 lines>...
    )
    ^
  File "/Users/rexrealingojr./Library/CloudStorage/GoogleDrive-rex15realingo@gmail.com/My Drive/Ai/.venv/lib/python3.13/site-packages/telegram/_bot.py", line 4610, in get_updates
    await self._post(
    ^^^^^^^^^^^^^^^^^
    ...<7 lines>...
    ),
    ^
  File "/Users/rexrealingojr./Library/CloudStorage/GoogleDrive-rex15realingo@gmail.com/My Drive/Ai/.venv/lib/python3.13/site-packages/telegram/_bot.py", line 697, in _post
    return await self._do_post(
           ^^^^^^^^^^^^^^^^^^^^
    ...<6 lines>...
    )
    ^
  File "/Users/rexrealingojr./Library/CloudStorage/GoogleDrive-rex15realingo@gmail.com/My Drive/Ai/.venv/lib/python3.13/site-packages/telegram/ext/_extbot.py", line 369, in _do_post
    return await super()._do_post(
           ^^^^^^^^^^^^^^^^^^^^^^^
    ...<6 lines>...
    )
    ^
  File "/Users/rexrealingojr./Library/CloudStorage/GoogleDrive-rex15realingo@gmail.com/My Drive/Ai/.venv/lib/python3.13/site-packages/telegram/_bot.py", line 726, in _do_post
    result = await request.post(
             ^^^^^^^^^^^^^^^^^^^
    ...<6 lines>...
    )
    ^
  File "/Users/rexrealingojr./Library/CloudStorage/GoogleDrive-rex15realingo@gmail.com/My Drive/Ai/.venv/lib/python3.13/site-packages/telegram/request/_baserequest.py", line 197, in post
    result = await self._request_wrapper(
             ^^^^^^^^^^^^^^^^^^^^^^^^^^^^
    ...<7 lines>...
    )
    ^
  File "/Users/rexrealingojr./Library/CloudStorage/GoogleDrive-rex15realingo@gmail.com/My Drive/Ai/.venv/lib/python3.13/site-packages/telegram/request/_baserequest.py", line 374, in _request_wrapper
    raise exception
telegram.error.Conflict: Conflict: terminated by other getUpdates request; make sure that only one bot instance is running
INFO:httpx:HTTP Request: POST https://api.telegram.org/bot7779786808:AAHul6zZde15UvoPbGb5aMm-KvtvROpqfB8/getUpdates "HTTP/1.1 200 OK"
ERROR:telegram.ext.Updater:Error while calling `get_updates` one more time to mark all fetched updates as read: %s. Suppressing error to ensure graceful shutdown. When polling for updates is restarted, updates may be fetched again. Please adjust timeouts via `ApplicationBuilder` or the parameter `get_updates_request` of `Bot`.
Traceback (most recent call last):
  File "/Users/rexrealingojr./Library/CloudStorage/GoogleDrive-rex15realingo@gmail.com/My Drive/Ai/.venv/lib/python3.13/site-packages/httpx/_transports/default.py", line 101, in map_httpcore_exceptions
    yield
  File "/Users/rexrealingojr./Library/CloudStorage/GoogleDrive-rex15realingo@gmail.com/My Drive/Ai/.venv/lib/python3.13/site-packages/httpx/_transports/default.py", line 394, in handle_async_request
    resp = await self._pool.handle_async_request(req)
           ^^^^^^^^^^^^^^^^^^^^^^^^^^^^^^^^^^^^^^^^^^
  File "/Users/rexrealingojr./Library/CloudStorage/GoogleDrive-rex15realingo@gmail.com/My Drive/Ai/.venv/lib/python3.13/site-packages/httpcore/_async/connection_pool.py", line 256, in handle_async_request
    raise exc from None
  File "/Users/rexrealingojr./Library/CloudStorage/GoogleDrive-rex15realingo@gmail.com/My Drive/Ai/.venv/lib/python3.13/site-packages/httpcore/_async/connection_pool.py", line 236, in handle_async_request
    response = await connection.handle_async_request(
               ^^^^^^^^^^^^^^^^^^^^^^^^^^^^^^^^^^^^^^
        pool_request.request
        ^^^^^^^^^^^^^^^^^^^^
    )
    ^
  File "/Users/rexrealingojr./Library/CloudStorage/GoogleDrive-rex15realingo@gmail.com/My Drive/Ai/.venv/lib/python3.13/site-packages/httpcore/_async/connection.py", line 101, in handle_async_request
    raise exc
  File "/Users/rexrealingojr./Library/CloudStorage/GoogleDrive-rex15realingo@gmail.com/My Drive/Ai/.venv/lib/python3.13/site-packages/httpcore/_async/connection.py", line 78, in handle_async_request
    stream = await self._connect(request)
             ^^^^^^^^^^^^^^^^^^^^^^^^^^^^
  File "/Users/rexrealingojr./Library/CloudStorage/GoogleDrive-rex15realingo@gmail.com/My Drive/Ai/.venv/lib/python3.13/site-packages/httpcore/_async/connection.py", line 124, in _connect
    stream = await self._network_backend.connect_tcp(**kwargs)
             ^^^^^^^^^^^^^^^^^^^^^^^^^^^^^^^^^^^^^^^^^^^^^^^^^
  File "/Users/rexrealingojr./Library/CloudStorage/GoogleDrive-rex15realingo@gmail.com/My Drive/Ai/.venv/lib/python3.13/site-packages/httpcore/_backends/auto.py", line 31, in connect_tcp
    return await self._backend.connect_tcp(
           ^^^^^^^^^^^^^^^^^^^^^^^^^^^^^^^^
    ...<5 lines>...
    )
    ^
  File "/Users/rexrealingojr./Library/CloudStorage/GoogleDrive-rex15realingo@gmail.com/My Drive/Ai/.venv/lib/python3.13/site-packages/httpcore/_backends/anyio.py", line 113, in connect_tcp
    with map_exceptions(exc_map):
         ~~~~~~~~~~~~~~^^^^^^^^^
  File "/opt/homebrew/Cellar/python@3.13/3.13.5/Frameworks/Python.framework/Versions/3.13/lib/python3.13/contextlib.py", line 162, in __exit__
    self.gen.throw(value)
    ~~~~~~~~~~~~~~^^^^^^^
  File "/Users/rexrealingojr./Library/CloudStorage/GoogleDrive-rex15realingo@gmail.com/My Drive/Ai/.venv/lib/python3.13/site-packages/httpcore/_exceptions.py", line 14, in map_exceptions
    raise to_exc(exc) from exc
httpcore.ConnectError: [Errno 8] nodename nor servname provided, or not known

The above exception was the direct cause of the following exception:

Traceback (most recent call last):
  File "/Users/rexrealingojr./Library/CloudStorage/GoogleDrive-rex15realingo@gmail.com/My Drive/Ai/.venv/lib/python3.13/site-packages/telegram/request/_httpxrequest.py", line 273, in do_request
    res = await self._client.request(
          ^^^^^^^^^^^^^^^^^^^^^^^^^^^
    ...<6 lines>...
    )
    ^
  File "/Users/rexrealingojr./Library/CloudStorage/GoogleDrive-rex15realingo@gmail.com/My Drive/Ai/.venv/lib/python3.13/site-packages/httpx/_client.py", line 1540, in request
    return await self.send(request, auth=auth, follow_redirects=follow_redirects)
           ^^^^^^^^^^^^^^^^^^^^^^^^^^^^^^^^^^^^^^^^^^^^^^^^^^^^^^^^^^^^^^^^^^^^^^
  File "/Users/rexrealingojr./Library/CloudStorage/GoogleDrive-rex15realingo@gmail.com/My Drive/Ai/.venv/lib/python3.13/site-packages/httpx/_client.py", line 1629, in send
    response = await self._send_handling_auth(
               ^^^^^^^^^^^^^^^^^^^^^^^^^^^^^^^
    ...<4 lines>...
    )
    ^
  File "/Users/rexrealingojr./Library/CloudStorage/GoogleDrive-rex15realingo@gmail.com/My Drive/Ai/.venv/lib/python3.13/site-packages/httpx/_client.py", line 1657, in _send_handling_auth
    response = await self._send_handling_redirects(
               ^^^^^^^^^^^^^^^^^^^^^^^^^^^^^^^^^^^^
    ...<3 lines>...
    )
    ^
  File "/Users/rexrealingojr./Library/CloudStorage/GoogleDrive-rex15realingo@gmail.com/My Drive/Ai/.venv/lib/python3.13/site-packages/httpx/_client.py", line 1694, in _send_handling_redirects
    response = await self._send_single_request(request)
               ^^^^^^^^^^^^^^^^^^^^^^^^^^^^^^^^^^^^^^^^
  File "/Users/rexrealingojr./Library/CloudStorage/GoogleDrive-rex15realingo@gmail.com/My Drive/Ai/.venv/lib/python3.13/site-packages/httpx/_client.py", line 1730, in _send_single_request
    response = await transport.handle_async_request(request)
               ^^^^^^^^^^^^^^^^^^^^^^^^^^^^^^^^^^^^^^^^^^^^^
  File "/Users/rexrealingojr./Library/CloudStorage/GoogleDrive-rex15realingo@gmail.com/My Drive/Ai/.venv/lib/python3.13/site-packages/httpx/_transports/default.py", line 393, in handle_async_request
    with map_httpcore_exceptions():
         ~~~~~~~~~~~~~~~~~~~~~~~^^
  File "/opt/homebrew/Cellar/python@3.13/3.13.5/Frameworks/Python.framework/Versions/3.13/lib/python3.13/contextlib.py", line 162, in __exit__
    self.gen.throw(value)
    ~~~~~~~~~~~~~~^^^^^^^
  File "/Users/rexrealingojr./Library/CloudStorage/GoogleDrive-rex15realingo@gmail.com/My Drive/Ai/.venv/lib/python3.13/site-packages/httpx/_transports/default.py", line 118, in map_httpcore_exceptions
    raise mapped_exc(message) from exc
httpx.ConnectError: [Errno 8] nodename nor servname provided, or not known

The above exception was the direct cause of the following exception:

Traceback (most recent call last):
  File "/Users/rexrealingojr./Library/CloudStorage/GoogleDrive-rex15realingo@gmail.com/My Drive/Ai/.venv/lib/python3.13/site-packages/telegram/ext/_updater.py", line 399, in _get_updates_cleanup
    await self.bot.get_updates(
    ...<4 lines>...
    )
  File "/Users/rexrealingojr./Library/CloudStorage/GoogleDrive-rex15realingo@gmail.com/My Drive/Ai/.venv/lib/python3.13/site-packages/telegram/ext/_extbot.py", line 669, in get_updates
    updates = await super().get_updates(
              ^^^^^^^^^^^^^^^^^^^^^^^^^^
    ...<9 lines>...
    )
    ^
  File "/Users/rexrealingojr./Library/CloudStorage/GoogleDrive-rex15realingo@gmail.com/My Drive/Ai/.venv/lib/python3.13/site-packages/telegram/_bot.py", line 4610, in get_updates
    await self._post(
    ^^^^^^^^^^^^^^^^^
    ...<7 lines>...
    ),
    ^
  File "/Users/rexrealingojr./Library/CloudStorage/GoogleDrive-rex15realingo@gmail.com/My Drive/Ai/.venv/lib/python3.13/site-packages/telegram/_bot.py", line 697, in _post
    return await self._do_post(
           ^^^^^^^^^^^^^^^^^^^^
    ...<6 lines>...
    )
    ^
  File "/Users/rexrealingojr./Library/CloudStorage/GoogleDrive-rex15realingo@gmail.com/My Drive/Ai/.venv/lib/python3.13/site-packages/telegram/ext/_extbot.py", line 369, in _do_post
    return await super()._do_post(
           ^^^^^^^^^^^^^^^^^^^^^^^
    ...<6 lines>...
    )
    ^
  File "/Users/rexrealingojr./Library/CloudStorage/GoogleDrive-rex15realingo@gmail.com/My Drive/Ai/.venv/lib/python3.13/site-packages/telegram/_bot.py", line 726, in _do_post
    result = await request.post(
             ^^^^^^^^^^^^^^^^^^^
    ...<6 lines>...
    )
    ^
  File "/Users/rexrealingojr./Library/CloudStorage/GoogleDrive-rex15realingo@gmail.com/My Drive/Ai/.venv/lib/python3.13/site-packages/telegram/request/_baserequest.py", line 197, in post
    result = await self._request_wrapper(
             ^^^^^^^^^^^^^^^^^^^^^^^^^^^^
    ...<7 lines>...
    )
    ^
  File "/Users/rexrealingojr./Library/CloudStorage/GoogleDrive-rex15realingo@gmail.com/My Drive/Ai/.venv/lib/python3.13/site-packages/telegram/request/_baserequest.py", line 304, in _request_wrapper
    code, payload = await self.do_request(
                    ^^^^^^^^^^^^^^^^^^^^^^
    ...<7 lines>...
    )
    ^
  File "/Users/rexrealingojr./Library/CloudStorage/GoogleDrive-rex15realingo@gmail.com/My Drive/Ai/.venv/lib/python3.13/site-packages/telegram/request/_httpxrequest.py", line 297, in do_request
    raise NetworkError(f"httpx.{err.__class__.__name__}: {err}") from err
telegram.error.NetworkError: httpx.ConnectError: [Errno 8] nodename nor servname provided, or not known
INFO:telegram.ext.Application:Application is stopping. This might take a moment.
INFO:telegram.ext.Application:Application.stop() complete
ü§ñ Bot is running...
